{
 "cells": [
  {
   "cell_type": "code",
   "execution_count": 1,
   "metadata": {},
   "outputs": [
    {
     "name": "stdout",
     "output_type": "stream",
     "text": [
      "['batches.meta', 'data_batch_1', 'data_batch_2', 'data_batch_3', 'data_batch_4', 'data_batch_5', 'readme.html', 'test_batch']\n"
     ]
    }
   ],
   "source": [
    "import tensorflow as tf\n",
    "import numpy as np\n",
    "import pickle\n",
    "import os\n",
    "\n",
    "CIFAR_DIR = './cifar-10-batches-py'\n",
    "print(os.listdir(CIFAR_DIR))"
   ]
  },
  {
   "cell_type": "code",
   "execution_count": 2,
   "metadata": {},
   "outputs": [
    {
     "name": "stdout",
     "output_type": "stream",
     "text": [
      "(50000, 3072)\n",
      "(50000,)\n",
      "(10000, 3072)\n",
      "(10000,)\n"
     ]
    }
   ],
   "source": [
    "def load_data(filename):\n",
    "    with open(filename, 'rb') as f:\n",
    "        data = pickle.load(f, encoding='bytes')\n",
    "        return data[b'data'], data[b'labels']\n",
    "\n",
    "class CifarData:\n",
    "    def __init__(self, filenames, need_shuffle):\n",
    "        all_data = []\n",
    "        all_labels = []\n",
    "        for filename in filenames:\n",
    "            data, labels = load_data(filename)\n",
    "            all_data.append(data)\n",
    "            all_labels.append(labels)\n",
    "        self._data = np.vstack(all_data)\n",
    "        self._data = self._data / 127.5 - 1  # 为了提高预测准确率，需要对数据进行归一化\n",
    "        self._labels = np.hstack(all_labels)\n",
    "        print(self._data.shape)\n",
    "        print(self._labels.shape)\n",
    "        \n",
    "        self._num_examples = self._data.shape[0]\n",
    "        self._need_shuffle = need_shuffle\n",
    "        self._indicator = 0  # 当前数据集指明遍历的位置\n",
    "        if self._need_shuffle:\n",
    "            self._shuffle_data()\n",
    "    \n",
    "    def _shuffle_data(self):\n",
    "        p = np.random.permutation(self._num_examples)  # 索引进行混排\n",
    "        self._data = self._data[p]\n",
    "        self._labels = self._labels[p]\n",
    "    \n",
    "    def next_batch(self, batch_size):\n",
    "        \"\"\"返回batch_size个样本\"\"\"\n",
    "        end_indicator = self._indicator + batch_size\n",
    "        if end_indicator > self._num_examples:\n",
    "            if self._need_shuffle:\n",
    "                self._shuffle_data()\n",
    "                self._indicator = 0\n",
    "                end_indicator = batch_size\n",
    "            else:\n",
    "                raise Exception(\"have no more examples\")\n",
    "        if end_indicator > self._num_examples:\n",
    "            raise Exception(\"batch size is larger than all examples\")\n",
    "        batch_data = self._data[self._indicator: end_indicator]\n",
    "        batch_labels = self._labels[self._indicator: end_indicator]\n",
    "        self._indicator = end_indicator\n",
    "        return batch_data, batch_labels\n",
    "\n",
    "train_filenames = [os.path.join(CIFAR_DIR, 'data_batch_%d' % i) for i in range(1, 6)]\n",
    "test_filenames = [os.path.join(CIFAR_DIR, 'test_batch')]\n",
    "\n",
    "train_data = CifarData(train_filenames, True)\n",
    "test_data = CifarData(test_filenames, False)"
   ]
  },
  {
   "cell_type": "code",
   "execution_count": 3,
   "metadata": {},
   "outputs": [
    {
     "name": "stdout",
     "output_type": "stream",
     "text": [
      "WARNING:tensorflow:From <ipython-input-3-b028688c9636>:31: conv2d (from tensorflow.python.layers.convolutional) is deprecated and will be removed in a future version.\n",
      "Instructions for updating:\n",
      "Use `tf.keras.layers.Conv2D` instead.\n",
      "WARNING:tensorflow:From D:\\Users\\Charles\\Anaconda3\\lib\\site-packages\\tensorflow\\python\\ops\\init_ops.py:1251: calling VarianceScaling.__init__ (from tensorflow.python.ops.init_ops) with dtype is deprecated and will be removed in a future version.\n",
      "Instructions for updating:\n",
      "Call initializer instance with the dtype argument instead of passing it to the constructor\n",
      "WARNING:tensorflow:Entity <bound method Conv.call of <tensorflow.python.layers.convolutional.Conv2D object at 0x0000029C742C0DC8>> could not be transformed and will be executed as-is. Please report this to the AutgoGraph team. When filing the bug, set the verbosity to 10 (on Linux, `export AUTOGRAPH_VERBOSITY=10`) and attach the full output. Cause: converting <bound method Conv.call of <tensorflow.python.layers.convolutional.Conv2D object at 0x0000029C742C0DC8>>: AssertionError: Bad argument number for Name: 3, expecting 4\n",
      "WARNING: Entity <bound method Conv.call of <tensorflow.python.layers.convolutional.Conv2D object at 0x0000029C742C0DC8>> could not be transformed and will be executed as-is. Please report this to the AutgoGraph team. When filing the bug, set the verbosity to 10 (on Linux, `export AUTOGRAPH_VERBOSITY=10`) and attach the full output. Cause: converting <bound method Conv.call of <tensorflow.python.layers.convolutional.Conv2D object at 0x0000029C742C0DC8>>: AssertionError: Bad argument number for Name: 3, expecting 4\n",
      "WARNING:tensorflow:From <ipython-input-3-b028688c9636>:33: max_pooling2d (from tensorflow.python.layers.pooling) is deprecated and will be removed in a future version.\n",
      "Instructions for updating:\n",
      "Use keras.layers.MaxPooling2D instead.\n",
      "WARNING:tensorflow:Entity <bound method Pooling2D.call of <tensorflow.python.layers.pooling.MaxPooling2D object at 0x0000029C6AC97F08>> could not be transformed and will be executed as-is. Please report this to the AutgoGraph team. When filing the bug, set the verbosity to 10 (on Linux, `export AUTOGRAPH_VERBOSITY=10`) and attach the full output. Cause: converting <bound method Pooling2D.call of <tensorflow.python.layers.pooling.MaxPooling2D object at 0x0000029C6AC97F08>>: AssertionError: Bad argument number for Name: 3, expecting 4\n",
      "WARNING: Entity <bound method Pooling2D.call of <tensorflow.python.layers.pooling.MaxPooling2D object at 0x0000029C6AC97F08>> could not be transformed and will be executed as-is. Please report this to the AutgoGraph team. When filing the bug, set the verbosity to 10 (on Linux, `export AUTOGRAPH_VERBOSITY=10`) and attach the full output. Cause: converting <bound method Pooling2D.call of <tensorflow.python.layers.pooling.MaxPooling2D object at 0x0000029C6AC97F08>>: AssertionError: Bad argument number for Name: 3, expecting 4\n",
      "WARNING:tensorflow:Entity <bound method Conv.call of <tensorflow.python.layers.convolutional.Conv2D object at 0x0000029C742AF708>> could not be transformed and will be executed as-is. Please report this to the AutgoGraph team. When filing the bug, set the verbosity to 10 (on Linux, `export AUTOGRAPH_VERBOSITY=10`) and attach the full output. Cause: converting <bound method Conv.call of <tensorflow.python.layers.convolutional.Conv2D object at 0x0000029C742AF708>>: AssertionError: Bad argument number for Name: 3, expecting 4\n",
      "WARNING: Entity <bound method Conv.call of <tensorflow.python.layers.convolutional.Conv2D object at 0x0000029C742AF708>> could not be transformed and will be executed as-is. Please report this to the AutgoGraph team. When filing the bug, set the verbosity to 10 (on Linux, `export AUTOGRAPH_VERBOSITY=10`) and attach the full output. Cause: converting <bound method Conv.call of <tensorflow.python.layers.convolutional.Conv2D object at 0x0000029C742AF708>>: AssertionError: Bad argument number for Name: 3, expecting 4\n",
      "WARNING:tensorflow:Entity <bound method Conv.call of <tensorflow.python.layers.convolutional.Conv2D object at 0x0000029C742AF708>> could not be transformed and will be executed as-is. Please report this to the AutgoGraph team. When filing the bug, set the verbosity to 10 (on Linux, `export AUTOGRAPH_VERBOSITY=10`) and attach the full output. Cause: converting <bound method Conv.call of <tensorflow.python.layers.convolutional.Conv2D object at 0x0000029C742AF708>>: AssertionError: Bad argument number for Name: 3, expecting 4\n",
      "WARNING: Entity <bound method Conv.call of <tensorflow.python.layers.convolutional.Conv2D object at 0x0000029C742AF708>> could not be transformed and will be executed as-is. Please report this to the AutgoGraph team. When filing the bug, set the verbosity to 10 (on Linux, `export AUTOGRAPH_VERBOSITY=10`) and attach the full output. Cause: converting <bound method Conv.call of <tensorflow.python.layers.convolutional.Conv2D object at 0x0000029C742AF708>>: AssertionError: Bad argument number for Name: 3, expecting 4\n",
      "WARNING:tensorflow:Entity <bound method Conv.call of <tensorflow.python.layers.convolutional.Conv2D object at 0x0000029C742AF248>> could not be transformed and will be executed as-is. Please report this to the AutgoGraph team. When filing the bug, set the verbosity to 10 (on Linux, `export AUTOGRAPH_VERBOSITY=10`) and attach the full output. Cause: converting <bound method Conv.call of <tensorflow.python.layers.convolutional.Conv2D object at 0x0000029C742AF248>>: AssertionError: Bad argument number for Name: 3, expecting 4\n",
      "WARNING: Entity <bound method Conv.call of <tensorflow.python.layers.convolutional.Conv2D object at 0x0000029C742AF248>> could not be transformed and will be executed as-is. Please report this to the AutgoGraph team. When filing the bug, set the verbosity to 10 (on Linux, `export AUTOGRAPH_VERBOSITY=10`) and attach the full output. Cause: converting <bound method Conv.call of <tensorflow.python.layers.convolutional.Conv2D object at 0x0000029C742AF248>>: AssertionError: Bad argument number for Name: 3, expecting 4\n",
      "WARNING:tensorflow:Entity <bound method Conv.call of <tensorflow.python.layers.convolutional.Conv2D object at 0x0000029C742AF708>> could not be transformed and will be executed as-is. Please report this to the AutgoGraph team. When filing the bug, set the verbosity to 10 (on Linux, `export AUTOGRAPH_VERBOSITY=10`) and attach the full output. Cause: converting <bound method Conv.call of <tensorflow.python.layers.convolutional.Conv2D object at 0x0000029C742AF708>>: AssertionError: Bad argument number for Name: 3, expecting 4\n",
      "WARNING: Entity <bound method Conv.call of <tensorflow.python.layers.convolutional.Conv2D object at 0x0000029C742AF708>> could not be transformed and will be executed as-is. Please report this to the AutgoGraph team. When filing the bug, set the verbosity to 10 (on Linux, `export AUTOGRAPH_VERBOSITY=10`) and attach the full output. Cause: converting <bound method Conv.call of <tensorflow.python.layers.convolutional.Conv2D object at 0x0000029C742AF708>>: AssertionError: Bad argument number for Name: 3, expecting 4\n",
      "WARNING:tensorflow:Entity <bound method Conv.call of <tensorflow.python.layers.convolutional.Conv2D object at 0x0000029C742AF248>> could not be transformed and will be executed as-is. Please report this to the AutgoGraph team. When filing the bug, set the verbosity to 10 (on Linux, `export AUTOGRAPH_VERBOSITY=10`) and attach the full output. Cause: converting <bound method Conv.call of <tensorflow.python.layers.convolutional.Conv2D object at 0x0000029C742AF248>>: AssertionError: Bad argument number for Name: 3, expecting 4\n",
      "WARNING: Entity <bound method Conv.call of <tensorflow.python.layers.convolutional.Conv2D object at 0x0000029C742AF248>> could not be transformed and will be executed as-is. Please report this to the AutgoGraph team. When filing the bug, set the verbosity to 10 (on Linux, `export AUTOGRAPH_VERBOSITY=10`) and attach the full output. Cause: converting <bound method Conv.call of <tensorflow.python.layers.convolutional.Conv2D object at 0x0000029C742AF248>>: AssertionError: Bad argument number for Name: 3, expecting 4\n",
      "WARNING:tensorflow:Entity <bound method Conv.call of <tensorflow.python.layers.convolutional.Conv2D object at 0x0000029C742AF248>> could not be transformed and will be executed as-is. Please report this to the AutgoGraph team. When filing the bug, set the verbosity to 10 (on Linux, `export AUTOGRAPH_VERBOSITY=10`) and attach the full output. Cause: converting <bound method Conv.call of <tensorflow.python.layers.convolutional.Conv2D object at 0x0000029C742AF248>>: AssertionError: Bad argument number for Name: 3, expecting 4\n"
     ]
    },
    {
     "name": "stdout",
     "output_type": "stream",
     "text": [
      "WARNING: Entity <bound method Conv.call of <tensorflow.python.layers.convolutional.Conv2D object at 0x0000029C742AF248>> could not be transformed and will be executed as-is. Please report this to the AutgoGraph team. When filing the bug, set the verbosity to 10 (on Linux, `export AUTOGRAPH_VERBOSITY=10`) and attach the full output. Cause: converting <bound method Conv.call of <tensorflow.python.layers.convolutional.Conv2D object at 0x0000029C742AF248>>: AssertionError: Bad argument number for Name: 3, expecting 4\n",
      "WARNING:tensorflow:Entity <bound method Conv.call of <tensorflow.python.layers.convolutional.Conv2D object at 0x0000029C742AF248>> could not be transformed and will be executed as-is. Please report this to the AutgoGraph team. When filing the bug, set the verbosity to 10 (on Linux, `export AUTOGRAPH_VERBOSITY=10`) and attach the full output. Cause: converting <bound method Conv.call of <tensorflow.python.layers.convolutional.Conv2D object at 0x0000029C742AF248>>: AssertionError: Bad argument number for Name: 3, expecting 4\n",
      "WARNING: Entity <bound method Conv.call of <tensorflow.python.layers.convolutional.Conv2D object at 0x0000029C742AF248>> could not be transformed and will be executed as-is. Please report this to the AutgoGraph team. When filing the bug, set the verbosity to 10 (on Linux, `export AUTOGRAPH_VERBOSITY=10`) and attach the full output. Cause: converting <bound method Conv.call of <tensorflow.python.layers.convolutional.Conv2D object at 0x0000029C742AF248>>: AssertionError: Bad argument number for Name: 3, expecting 4\n",
      "WARNING:tensorflow:Entity <bound method Conv.call of <tensorflow.python.layers.convolutional.Conv2D object at 0x0000029C6AC978C8>> could not be transformed and will be executed as-is. Please report this to the AutgoGraph team. When filing the bug, set the verbosity to 10 (on Linux, `export AUTOGRAPH_VERBOSITY=10`) and attach the full output. Cause: converting <bound method Conv.call of <tensorflow.python.layers.convolutional.Conv2D object at 0x0000029C6AC978C8>>: AssertionError: Bad argument number for Name: 3, expecting 4\n",
      "WARNING: Entity <bound method Conv.call of <tensorflow.python.layers.convolutional.Conv2D object at 0x0000029C6AC978C8>> could not be transformed and will be executed as-is. Please report this to the AutgoGraph team. When filing the bug, set the verbosity to 10 (on Linux, `export AUTOGRAPH_VERBOSITY=10`) and attach the full output. Cause: converting <bound method Conv.call of <tensorflow.python.layers.convolutional.Conv2D object at 0x0000029C6AC978C8>>: AssertionError: Bad argument number for Name: 3, expecting 4\n",
      "WARNING:tensorflow:Entity <bound method Conv.call of <tensorflow.python.layers.convolutional.Conv2D object at 0x0000029C742AF248>> could not be transformed and will be executed as-is. Please report this to the AutgoGraph team. When filing the bug, set the verbosity to 10 (on Linux, `export AUTOGRAPH_VERBOSITY=10`) and attach the full output. Cause: converting <bound method Conv.call of <tensorflow.python.layers.convolutional.Conv2D object at 0x0000029C742AF248>>: AssertionError: Bad argument number for Name: 3, expecting 4\n",
      "WARNING: Entity <bound method Conv.call of <tensorflow.python.layers.convolutional.Conv2D object at 0x0000029C742AF248>> could not be transformed and will be executed as-is. Please report this to the AutgoGraph team. When filing the bug, set the verbosity to 10 (on Linux, `export AUTOGRAPH_VERBOSITY=10`) and attach the full output. Cause: converting <bound method Conv.call of <tensorflow.python.layers.convolutional.Conv2D object at 0x0000029C742AF248>>: AssertionError: Bad argument number for Name: 3, expecting 4\n",
      "WARNING:tensorflow:Entity <bound method Conv.call of <tensorflow.python.layers.convolutional.Conv2D object at 0x0000029C742AF708>> could not be transformed and will be executed as-is. Please report this to the AutgoGraph team. When filing the bug, set the verbosity to 10 (on Linux, `export AUTOGRAPH_VERBOSITY=10`) and attach the full output. Cause: converting <bound method Conv.call of <tensorflow.python.layers.convolutional.Conv2D object at 0x0000029C742AF708>>: AssertionError: Bad argument number for Name: 3, expecting 4\n",
      "WARNING: Entity <bound method Conv.call of <tensorflow.python.layers.convolutional.Conv2D object at 0x0000029C742AF708>> could not be transformed and will be executed as-is. Please report this to the AutgoGraph team. When filing the bug, set the verbosity to 10 (on Linux, `export AUTOGRAPH_VERBOSITY=10`) and attach the full output. Cause: converting <bound method Conv.call of <tensorflow.python.layers.convolutional.Conv2D object at 0x0000029C742AF708>>: AssertionError: Bad argument number for Name: 3, expecting 4\n",
      "WARNING:tensorflow:Entity <bound method Conv.call of <tensorflow.python.layers.convolutional.Conv2D object at 0x0000029C742AF708>> could not be transformed and will be executed as-is. Please report this to the AutgoGraph team. When filing the bug, set the verbosity to 10 (on Linux, `export AUTOGRAPH_VERBOSITY=10`) and attach the full output. Cause: converting <bound method Conv.call of <tensorflow.python.layers.convolutional.Conv2D object at 0x0000029C742AF708>>: AssertionError: Bad argument number for Name: 3, expecting 4\n",
      "WARNING: Entity <bound method Conv.call of <tensorflow.python.layers.convolutional.Conv2D object at 0x0000029C742AF708>> could not be transformed and will be executed as-is. Please report this to the AutgoGraph team. When filing the bug, set the verbosity to 10 (on Linux, `export AUTOGRAPH_VERBOSITY=10`) and attach the full output. Cause: converting <bound method Conv.call of <tensorflow.python.layers.convolutional.Conv2D object at 0x0000029C742AF708>>: AssertionError: Bad argument number for Name: 3, expecting 4\n",
      "WARNING:tensorflow:Entity <bound method Conv.call of <tensorflow.python.layers.convolutional.Conv2D object at 0x0000029C6AC978C8>> could not be transformed and will be executed as-is. Please report this to the AutgoGraph team. When filing the bug, set the verbosity to 10 (on Linux, `export AUTOGRAPH_VERBOSITY=10`) and attach the full output. Cause: converting <bound method Conv.call of <tensorflow.python.layers.convolutional.Conv2D object at 0x0000029C6AC978C8>>: AssertionError: Bad argument number for Name: 3, expecting 4\n",
      "WARNING: Entity <bound method Conv.call of <tensorflow.python.layers.convolutional.Conv2D object at 0x0000029C6AC978C8>> could not be transformed and will be executed as-is. Please report this to the AutgoGraph team. When filing the bug, set the verbosity to 10 (on Linux, `export AUTOGRAPH_VERBOSITY=10`) and attach the full output. Cause: converting <bound method Conv.call of <tensorflow.python.layers.convolutional.Conv2D object at 0x0000029C6AC978C8>>: AssertionError: Bad argument number for Name: 3, expecting 4\n",
      "WARNING:tensorflow:Entity <bound method Conv.call of <tensorflow.python.layers.convolutional.Conv2D object at 0x0000029C742AF708>> could not be transformed and will be executed as-is. Please report this to the AutgoGraph team. When filing the bug, set the verbosity to 10 (on Linux, `export AUTOGRAPH_VERBOSITY=10`) and attach the full output. Cause: converting <bound method Conv.call of <tensorflow.python.layers.convolutional.Conv2D object at 0x0000029C742AF708>>: AssertionError: Bad argument number for Name: 3, expecting 4\n",
      "WARNING: Entity <bound method Conv.call of <tensorflow.python.layers.convolutional.Conv2D object at 0x0000029C742AF708>> could not be transformed and will be executed as-is. Please report this to the AutgoGraph team. When filing the bug, set the verbosity to 10 (on Linux, `export AUTOGRAPH_VERBOSITY=10`) and attach the full output. Cause: converting <bound method Conv.call of <tensorflow.python.layers.convolutional.Conv2D object at 0x0000029C742AF708>>: AssertionError: Bad argument number for Name: 3, expecting 4\n",
      "WARNING:tensorflow:Entity <bound method Conv.call of <tensorflow.python.layers.convolutional.Conv2D object at 0x0000029C6AC978C8>> could not be transformed and will be executed as-is. Please report this to the AutgoGraph team. When filing the bug, set the verbosity to 10 (on Linux, `export AUTOGRAPH_VERBOSITY=10`) and attach the full output. Cause: converting <bound method Conv.call of <tensorflow.python.layers.convolutional.Conv2D object at 0x0000029C6AC978C8>>: AssertionError: Bad argument number for Name: 3, expecting 4\n"
     ]
    },
    {
     "name": "stdout",
     "output_type": "stream",
     "text": [
      "WARNING: Entity <bound method Conv.call of <tensorflow.python.layers.convolutional.Conv2D object at 0x0000029C6AC978C8>> could not be transformed and will be executed as-is. Please report this to the AutgoGraph team. When filing the bug, set the verbosity to 10 (on Linux, `export AUTOGRAPH_VERBOSITY=10`) and attach the full output. Cause: converting <bound method Conv.call of <tensorflow.python.layers.convolutional.Conv2D object at 0x0000029C6AC978C8>>: AssertionError: Bad argument number for Name: 3, expecting 4\n",
      "WARNING:tensorflow:Entity <bound method Conv.call of <tensorflow.python.layers.convolutional.Conv2D object at 0x0000029C742AF708>> could not be transformed and will be executed as-is. Please report this to the AutgoGraph team. When filing the bug, set the verbosity to 10 (on Linux, `export AUTOGRAPH_VERBOSITY=10`) and attach the full output. Cause: converting <bound method Conv.call of <tensorflow.python.layers.convolutional.Conv2D object at 0x0000029C742AF708>>: AssertionError: Bad argument number for Name: 3, expecting 4\n",
      "WARNING: Entity <bound method Conv.call of <tensorflow.python.layers.convolutional.Conv2D object at 0x0000029C742AF708>> could not be transformed and will be executed as-is. Please report this to the AutgoGraph team. When filing the bug, set the verbosity to 10 (on Linux, `export AUTOGRAPH_VERBOSITY=10`) and attach the full output. Cause: converting <bound method Conv.call of <tensorflow.python.layers.convolutional.Conv2D object at 0x0000029C742AF708>>: AssertionError: Bad argument number for Name: 3, expecting 4\n",
      "WARNING:tensorflow:Entity <bound method Conv.call of <tensorflow.python.layers.convolutional.Conv2D object at 0x0000029C6AC978C8>> could not be transformed and will be executed as-is. Please report this to the AutgoGraph team. When filing the bug, set the verbosity to 10 (on Linux, `export AUTOGRAPH_VERBOSITY=10`) and attach the full output. Cause: converting <bound method Conv.call of <tensorflow.python.layers.convolutional.Conv2D object at 0x0000029C6AC978C8>>: AssertionError: Bad argument number for Name: 3, expecting 4\n",
      "WARNING: Entity <bound method Conv.call of <tensorflow.python.layers.convolutional.Conv2D object at 0x0000029C6AC978C8>> could not be transformed and will be executed as-is. Please report this to the AutgoGraph team. When filing the bug, set the verbosity to 10 (on Linux, `export AUTOGRAPH_VERBOSITY=10`) and attach the full output. Cause: converting <bound method Conv.call of <tensorflow.python.layers.convolutional.Conv2D object at 0x0000029C6AC978C8>>: AssertionError: Bad argument number for Name: 3, expecting 4\n",
      "WARNING:tensorflow:Entity <bound method Conv.call of <tensorflow.python.layers.convolutional.Conv2D object at 0x0000029C742AF708>> could not be transformed and will be executed as-is. Please report this to the AutgoGraph team. When filing the bug, set the verbosity to 10 (on Linux, `export AUTOGRAPH_VERBOSITY=10`) and attach the full output. Cause: converting <bound method Conv.call of <tensorflow.python.layers.convolutional.Conv2D object at 0x0000029C742AF708>>: AssertionError: Bad argument number for Name: 3, expecting 4\n",
      "WARNING: Entity <bound method Conv.call of <tensorflow.python.layers.convolutional.Conv2D object at 0x0000029C742AF708>> could not be transformed and will be executed as-is. Please report this to the AutgoGraph team. When filing the bug, set the verbosity to 10 (on Linux, `export AUTOGRAPH_VERBOSITY=10`) and attach the full output. Cause: converting <bound method Conv.call of <tensorflow.python.layers.convolutional.Conv2D object at 0x0000029C742AF708>>: AssertionError: Bad argument number for Name: 3, expecting 4\n",
      "WARNING:tensorflow:Entity <bound method Conv.call of <tensorflow.python.layers.convolutional.Conv2D object at 0x0000029C6AC978C8>> could not be transformed and will be executed as-is. Please report this to the AutgoGraph team. When filing the bug, set the verbosity to 10 (on Linux, `export AUTOGRAPH_VERBOSITY=10`) and attach the full output. Cause: converting <bound method Conv.call of <tensorflow.python.layers.convolutional.Conv2D object at 0x0000029C6AC978C8>>: AssertionError: Bad argument number for Name: 3, expecting 4\n",
      "WARNING: Entity <bound method Conv.call of <tensorflow.python.layers.convolutional.Conv2D object at 0x0000029C6AC978C8>> could not be transformed and will be executed as-is. Please report this to the AutgoGraph team. When filing the bug, set the verbosity to 10 (on Linux, `export AUTOGRAPH_VERBOSITY=10`) and attach the full output. Cause: converting <bound method Conv.call of <tensorflow.python.layers.convolutional.Conv2D object at 0x0000029C6AC978C8>>: AssertionError: Bad argument number for Name: 3, expecting 4\n",
      "WARNING:tensorflow:Entity <bound method Conv.call of <tensorflow.python.layers.convolutional.Conv2D object at 0x0000029C742AF708>> could not be transformed and will be executed as-is. Please report this to the AutgoGraph team. When filing the bug, set the verbosity to 10 (on Linux, `export AUTOGRAPH_VERBOSITY=10`) and attach the full output. Cause: converting <bound method Conv.call of <tensorflow.python.layers.convolutional.Conv2D object at 0x0000029C742AF708>>: AssertionError: Bad argument number for Name: 3, expecting 4\n",
      "WARNING: Entity <bound method Conv.call of <tensorflow.python.layers.convolutional.Conv2D object at 0x0000029C742AF708>> could not be transformed and will be executed as-is. Please report this to the AutgoGraph team. When filing the bug, set the verbosity to 10 (on Linux, `export AUTOGRAPH_VERBOSITY=10`) and attach the full output. Cause: converting <bound method Conv.call of <tensorflow.python.layers.convolutional.Conv2D object at 0x0000029C742AF708>>: AssertionError: Bad argument number for Name: 3, expecting 4\n",
      "WARNING:tensorflow:Entity <bound method Conv.call of <tensorflow.python.layers.convolutional.Conv2D object at 0x0000029C6AC978C8>> could not be transformed and will be executed as-is. Please report this to the AutgoGraph team. When filing the bug, set the verbosity to 10 (on Linux, `export AUTOGRAPH_VERBOSITY=10`) and attach the full output. Cause: converting <bound method Conv.call of <tensorflow.python.layers.convolutional.Conv2D object at 0x0000029C6AC978C8>>: AssertionError: Bad argument number for Name: 3, expecting 4\n",
      "WARNING: Entity <bound method Conv.call of <tensorflow.python.layers.convolutional.Conv2D object at 0x0000029C6AC978C8>> could not be transformed and will be executed as-is. Please report this to the AutgoGraph team. When filing the bug, set the verbosity to 10 (on Linux, `export AUTOGRAPH_VERBOSITY=10`) and attach the full output. Cause: converting <bound method Conv.call of <tensorflow.python.layers.convolutional.Conv2D object at 0x0000029C6AC978C8>>: AssertionError: Bad argument number for Name: 3, expecting 4\n",
      "WARNING:tensorflow:Entity <bound method Conv.call of <tensorflow.python.layers.convolutional.Conv2D object at 0x0000029C742AF708>> could not be transformed and will be executed as-is. Please report this to the AutgoGraph team. When filing the bug, set the verbosity to 10 (on Linux, `export AUTOGRAPH_VERBOSITY=10`) and attach the full output. Cause: converting <bound method Conv.call of <tensorflow.python.layers.convolutional.Conv2D object at 0x0000029C742AF708>>: AssertionError: Bad argument number for Name: 3, expecting 4\n",
      "WARNING: Entity <bound method Conv.call of <tensorflow.python.layers.convolutional.Conv2D object at 0x0000029C742AF708>> could not be transformed and will be executed as-is. Please report this to the AutgoGraph team. When filing the bug, set the verbosity to 10 (on Linux, `export AUTOGRAPH_VERBOSITY=10`) and attach the full output. Cause: converting <bound method Conv.call of <tensorflow.python.layers.convolutional.Conv2D object at 0x0000029C742AF708>>: AssertionError: Bad argument number for Name: 3, expecting 4\n",
      "WARNING:tensorflow:Entity <bound method Conv.call of <tensorflow.python.layers.convolutional.Conv2D object at 0x0000029C6AC978C8>> could not be transformed and will be executed as-is. Please report this to the AutgoGraph team. When filing the bug, set the verbosity to 10 (on Linux, `export AUTOGRAPH_VERBOSITY=10`) and attach the full output. Cause: converting <bound method Conv.call of <tensorflow.python.layers.convolutional.Conv2D object at 0x0000029C6AC978C8>>: AssertionError: Bad argument number for Name: 3, expecting 4\n"
     ]
    },
    {
     "name": "stdout",
     "output_type": "stream",
     "text": [
      "WARNING: Entity <bound method Conv.call of <tensorflow.python.layers.convolutional.Conv2D object at 0x0000029C6AC978C8>> could not be transformed and will be executed as-is. Please report this to the AutgoGraph team. When filing the bug, set the verbosity to 10 (on Linux, `export AUTOGRAPH_VERBOSITY=10`) and attach the full output. Cause: converting <bound method Conv.call of <tensorflow.python.layers.convolutional.Conv2D object at 0x0000029C6AC978C8>>: AssertionError: Bad argument number for Name: 3, expecting 4\n",
      "WARNING:tensorflow:Entity <bound method Conv.call of <tensorflow.python.layers.convolutional.Conv2D object at 0x0000029C742AF708>> could not be transformed and will be executed as-is. Please report this to the AutgoGraph team. When filing the bug, set the verbosity to 10 (on Linux, `export AUTOGRAPH_VERBOSITY=10`) and attach the full output. Cause: converting <bound method Conv.call of <tensorflow.python.layers.convolutional.Conv2D object at 0x0000029C742AF708>>: AssertionError: Bad argument number for Name: 3, expecting 4\n",
      "WARNING: Entity <bound method Conv.call of <tensorflow.python.layers.convolutional.Conv2D object at 0x0000029C742AF708>> could not be transformed and will be executed as-is. Please report this to the AutgoGraph team. When filing the bug, set the verbosity to 10 (on Linux, `export AUTOGRAPH_VERBOSITY=10`) and attach the full output. Cause: converting <bound method Conv.call of <tensorflow.python.layers.convolutional.Conv2D object at 0x0000029C742AF708>>: AssertionError: Bad argument number for Name: 3, expecting 4\n",
      "WARNING:tensorflow:Entity <bound method Conv.call of <tensorflow.python.layers.convolutional.Conv2D object at 0x0000029C6AC978C8>> could not be transformed and will be executed as-is. Please report this to the AutgoGraph team. When filing the bug, set the verbosity to 10 (on Linux, `export AUTOGRAPH_VERBOSITY=10`) and attach the full output. Cause: converting <bound method Conv.call of <tensorflow.python.layers.convolutional.Conv2D object at 0x0000029C6AC978C8>>: AssertionError: Bad argument number for Name: 3, expecting 4\n",
      "WARNING: Entity <bound method Conv.call of <tensorflow.python.layers.convolutional.Conv2D object at 0x0000029C6AC978C8>> could not be transformed and will be executed as-is. Please report this to the AutgoGraph team. When filing the bug, set the verbosity to 10 (on Linux, `export AUTOGRAPH_VERBOSITY=10`) and attach the full output. Cause: converting <bound method Conv.call of <tensorflow.python.layers.convolutional.Conv2D object at 0x0000029C6AC978C8>>: AssertionError: Bad argument number for Name: 3, expecting 4\n",
      "WARNING:tensorflow:Entity <bound method Conv.call of <tensorflow.python.layers.convolutional.Conv2D object at 0x0000029C742AF708>> could not be transformed and will be executed as-is. Please report this to the AutgoGraph team. When filing the bug, set the verbosity to 10 (on Linux, `export AUTOGRAPH_VERBOSITY=10`) and attach the full output. Cause: converting <bound method Conv.call of <tensorflow.python.layers.convolutional.Conv2D object at 0x0000029C742AF708>>: AssertionError: Bad argument number for Name: 3, expecting 4\n",
      "WARNING: Entity <bound method Conv.call of <tensorflow.python.layers.convolutional.Conv2D object at 0x0000029C742AF708>> could not be transformed and will be executed as-is. Please report this to the AutgoGraph team. When filing the bug, set the verbosity to 10 (on Linux, `export AUTOGRAPH_VERBOSITY=10`) and attach the full output. Cause: converting <bound method Conv.call of <tensorflow.python.layers.convolutional.Conv2D object at 0x0000029C742AF708>>: AssertionError: Bad argument number for Name: 3, expecting 4\n",
      "WARNING:tensorflow:Entity <bound method Conv.call of <tensorflow.python.layers.convolutional.Conv2D object at 0x0000029C6AC978C8>> could not be transformed and will be executed as-is. Please report this to the AutgoGraph team. When filing the bug, set the verbosity to 10 (on Linux, `export AUTOGRAPH_VERBOSITY=10`) and attach the full output. Cause: converting <bound method Conv.call of <tensorflow.python.layers.convolutional.Conv2D object at 0x0000029C6AC978C8>>: AssertionError: Bad argument number for Name: 3, expecting 4\n",
      "WARNING: Entity <bound method Conv.call of <tensorflow.python.layers.convolutional.Conv2D object at 0x0000029C6AC978C8>> could not be transformed and will be executed as-is. Please report this to the AutgoGraph team. When filing the bug, set the verbosity to 10 (on Linux, `export AUTOGRAPH_VERBOSITY=10`) and attach the full output. Cause: converting <bound method Conv.call of <tensorflow.python.layers.convolutional.Conv2D object at 0x0000029C6AC978C8>>: AssertionError: Bad argument number for Name: 3, expecting 4\n",
      "WARNING:tensorflow:Entity <bound method Conv.call of <tensorflow.python.layers.convolutional.Conv2D object at 0x0000029C742AF708>> could not be transformed and will be executed as-is. Please report this to the AutgoGraph team. When filing the bug, set the verbosity to 10 (on Linux, `export AUTOGRAPH_VERBOSITY=10`) and attach the full output. Cause: converting <bound method Conv.call of <tensorflow.python.layers.convolutional.Conv2D object at 0x0000029C742AF708>>: AssertionError: Bad argument number for Name: 3, expecting 4\n",
      "WARNING: Entity <bound method Conv.call of <tensorflow.python.layers.convolutional.Conv2D object at 0x0000029C742AF708>> could not be transformed and will be executed as-is. Please report this to the AutgoGraph team. When filing the bug, set the verbosity to 10 (on Linux, `export AUTOGRAPH_VERBOSITY=10`) and attach the full output. Cause: converting <bound method Conv.call of <tensorflow.python.layers.convolutional.Conv2D object at 0x0000029C742AF708>>: AssertionError: Bad argument number for Name: 3, expecting 4\n",
      "WARNING:tensorflow:Entity <bound method Conv.call of <tensorflow.python.layers.convolutional.Conv2D object at 0x0000029C6AC978C8>> could not be transformed and will be executed as-is. Please report this to the AutgoGraph team. When filing the bug, set the verbosity to 10 (on Linux, `export AUTOGRAPH_VERBOSITY=10`) and attach the full output. Cause: converting <bound method Conv.call of <tensorflow.python.layers.convolutional.Conv2D object at 0x0000029C6AC978C8>>: AssertionError: Bad argument number for Name: 3, expecting 4\n",
      "WARNING: Entity <bound method Conv.call of <tensorflow.python.layers.convolutional.Conv2D object at 0x0000029C6AC978C8>> could not be transformed and will be executed as-is. Please report this to the AutgoGraph team. When filing the bug, set the verbosity to 10 (on Linux, `export AUTOGRAPH_VERBOSITY=10`) and attach the full output. Cause: converting <bound method Conv.call of <tensorflow.python.layers.convolutional.Conv2D object at 0x0000029C6AC978C8>>: AssertionError: Bad argument number for Name: 3, expecting 4\n",
      "WARNING:tensorflow:Entity <bound method Conv.call of <tensorflow.python.layers.convolutional.Conv2D object at 0x0000029C742AF708>> could not be transformed and will be executed as-is. Please report this to the AutgoGraph team. When filing the bug, set the verbosity to 10 (on Linux, `export AUTOGRAPH_VERBOSITY=10`) and attach the full output. Cause: converting <bound method Conv.call of <tensorflow.python.layers.convolutional.Conv2D object at 0x0000029C742AF708>>: AssertionError: Bad argument number for Name: 3, expecting 4\n",
      "WARNING: Entity <bound method Conv.call of <tensorflow.python.layers.convolutional.Conv2D object at 0x0000029C742AF708>> could not be transformed and will be executed as-is. Please report this to the AutgoGraph team. When filing the bug, set the verbosity to 10 (on Linux, `export AUTOGRAPH_VERBOSITY=10`) and attach the full output. Cause: converting <bound method Conv.call of <tensorflow.python.layers.convolutional.Conv2D object at 0x0000029C742AF708>>: AssertionError: Bad argument number for Name: 3, expecting 4\n",
      "WARNING:tensorflow:Entity <bound method Conv.call of <tensorflow.python.layers.convolutional.Conv2D object at 0x0000029C6AC978C8>> could not be transformed and will be executed as-is. Please report this to the AutgoGraph team. When filing the bug, set the verbosity to 10 (on Linux, `export AUTOGRAPH_VERBOSITY=10`) and attach the full output. Cause: converting <bound method Conv.call of <tensorflow.python.layers.convolutional.Conv2D object at 0x0000029C6AC978C8>>: AssertionError: Bad argument number for Name: 3, expecting 4\n"
     ]
    },
    {
     "name": "stdout",
     "output_type": "stream",
     "text": [
      "WARNING: Entity <bound method Conv.call of <tensorflow.python.layers.convolutional.Conv2D object at 0x0000029C6AC978C8>> could not be transformed and will be executed as-is. Please report this to the AutgoGraph team. When filing the bug, set the verbosity to 10 (on Linux, `export AUTOGRAPH_VERBOSITY=10`) and attach the full output. Cause: converting <bound method Conv.call of <tensorflow.python.layers.convolutional.Conv2D object at 0x0000029C6AC978C8>>: AssertionError: Bad argument number for Name: 3, expecting 4\n",
      "WARNING:tensorflow:Entity <bound method Conv.call of <tensorflow.python.layers.convolutional.Conv2D object at 0x0000029C742AF708>> could not be transformed and will be executed as-is. Please report this to the AutgoGraph team. When filing the bug, set the verbosity to 10 (on Linux, `export AUTOGRAPH_VERBOSITY=10`) and attach the full output. Cause: converting <bound method Conv.call of <tensorflow.python.layers.convolutional.Conv2D object at 0x0000029C742AF708>>: AssertionError: Bad argument number for Name: 3, expecting 4\n",
      "WARNING: Entity <bound method Conv.call of <tensorflow.python.layers.convolutional.Conv2D object at 0x0000029C742AF708>> could not be transformed and will be executed as-is. Please report this to the AutgoGraph team. When filing the bug, set the verbosity to 10 (on Linux, `export AUTOGRAPH_VERBOSITY=10`) and attach the full output. Cause: converting <bound method Conv.call of <tensorflow.python.layers.convolutional.Conv2D object at 0x0000029C742AF708>>: AssertionError: Bad argument number for Name: 3, expecting 4\n",
      "WARNING:tensorflow:Entity <bound method Conv.call of <tensorflow.python.layers.convolutional.Conv2D object at 0x0000029C6AC978C8>> could not be transformed and will be executed as-is. Please report this to the AutgoGraph team. When filing the bug, set the verbosity to 10 (on Linux, `export AUTOGRAPH_VERBOSITY=10`) and attach the full output. Cause: converting <bound method Conv.call of <tensorflow.python.layers.convolutional.Conv2D object at 0x0000029C6AC978C8>>: AssertionError: Bad argument number for Name: 3, expecting 4\n",
      "WARNING: Entity <bound method Conv.call of <tensorflow.python.layers.convolutional.Conv2D object at 0x0000029C6AC978C8>> could not be transformed and will be executed as-is. Please report this to the AutgoGraph team. When filing the bug, set the verbosity to 10 (on Linux, `export AUTOGRAPH_VERBOSITY=10`) and attach the full output. Cause: converting <bound method Conv.call of <tensorflow.python.layers.convolutional.Conv2D object at 0x0000029C6AC978C8>>: AssertionError: Bad argument number for Name: 3, expecting 4\n",
      "WARNING:tensorflow:Entity <bound method Conv.call of <tensorflow.python.layers.convolutional.Conv2D object at 0x0000029C74AF1508>> could not be transformed and will be executed as-is. Please report this to the AutgoGraph team. When filing the bug, set the verbosity to 10 (on Linux, `export AUTOGRAPH_VERBOSITY=10`) and attach the full output. Cause: converting <bound method Conv.call of <tensorflow.python.layers.convolutional.Conv2D object at 0x0000029C74AF1508>>: AssertionError: Bad argument number for Name: 3, expecting 4\n",
      "WARNING: Entity <bound method Conv.call of <tensorflow.python.layers.convolutional.Conv2D object at 0x0000029C74AF1508>> could not be transformed and will be executed as-is. Please report this to the AutgoGraph team. When filing the bug, set the verbosity to 10 (on Linux, `export AUTOGRAPH_VERBOSITY=10`) and attach the full output. Cause: converting <bound method Conv.call of <tensorflow.python.layers.convolutional.Conv2D object at 0x0000029C74AF1508>>: AssertionError: Bad argument number for Name: 3, expecting 4\n",
      "WARNING:tensorflow:Entity <bound method Conv.call of <tensorflow.python.layers.convolutional.Conv2D object at 0x0000029C74C117C8>> could not be transformed and will be executed as-is. Please report this to the AutgoGraph team. When filing the bug, set the verbosity to 10 (on Linux, `export AUTOGRAPH_VERBOSITY=10`) and attach the full output. Cause: converting <bound method Conv.call of <tensorflow.python.layers.convolutional.Conv2D object at 0x0000029C74C117C8>>: AssertionError: Bad argument number for Name: 3, expecting 4\n",
      "WARNING: Entity <bound method Conv.call of <tensorflow.python.layers.convolutional.Conv2D object at 0x0000029C74C117C8>> could not be transformed and will be executed as-is. Please report this to the AutgoGraph team. When filing the bug, set the verbosity to 10 (on Linux, `export AUTOGRAPH_VERBOSITY=10`) and attach the full output. Cause: converting <bound method Conv.call of <tensorflow.python.layers.convolutional.Conv2D object at 0x0000029C74C117C8>>: AssertionError: Bad argument number for Name: 3, expecting 4\n",
      "WARNING:tensorflow:Entity <bound method Conv.call of <tensorflow.python.layers.convolutional.Conv2D object at 0x0000029C74BB4E48>> could not be transformed and will be executed as-is. Please report this to the AutgoGraph team. When filing the bug, set the verbosity to 10 (on Linux, `export AUTOGRAPH_VERBOSITY=10`) and attach the full output. Cause: converting <bound method Conv.call of <tensorflow.python.layers.convolutional.Conv2D object at 0x0000029C74BB4E48>>: AssertionError: Bad argument number for Name: 3, expecting 4\n",
      "WARNING: Entity <bound method Conv.call of <tensorflow.python.layers.convolutional.Conv2D object at 0x0000029C74BB4E48>> could not be transformed and will be executed as-is. Please report this to the AutgoGraph team. When filing the bug, set the verbosity to 10 (on Linux, `export AUTOGRAPH_VERBOSITY=10`) and attach the full output. Cause: converting <bound method Conv.call of <tensorflow.python.layers.convolutional.Conv2D object at 0x0000029C74BB4E48>>: AssertionError: Bad argument number for Name: 3, expecting 4\n",
      "WARNING:tensorflow:Entity <bound method Conv.call of <tensorflow.python.layers.convolutional.Conv2D object at 0x0000029C749D1088>> could not be transformed and will be executed as-is. Please report this to the AutgoGraph team. When filing the bug, set the verbosity to 10 (on Linux, `export AUTOGRAPH_VERBOSITY=10`) and attach the full output. Cause: converting <bound method Conv.call of <tensorflow.python.layers.convolutional.Conv2D object at 0x0000029C749D1088>>: AssertionError: Bad argument number for Name: 3, expecting 4\n",
      "WARNING: Entity <bound method Conv.call of <tensorflow.python.layers.convolutional.Conv2D object at 0x0000029C749D1088>> could not be transformed and will be executed as-is. Please report this to the AutgoGraph team. When filing the bug, set the verbosity to 10 (on Linux, `export AUTOGRAPH_VERBOSITY=10`) and attach the full output. Cause: converting <bound method Conv.call of <tensorflow.python.layers.convolutional.Conv2D object at 0x0000029C749D1088>>: AssertionError: Bad argument number for Name: 3, expecting 4\n",
      "WARNING:tensorflow:Entity <bound method Conv.call of <tensorflow.python.layers.convolutional.Conv2D object at 0x0000029C74BB4E48>> could not be transformed and will be executed as-is. Please report this to the AutgoGraph team. When filing the bug, set the verbosity to 10 (on Linux, `export AUTOGRAPH_VERBOSITY=10`) and attach the full output. Cause: converting <bound method Conv.call of <tensorflow.python.layers.convolutional.Conv2D object at 0x0000029C74BB4E48>>: AssertionError: Bad argument number for Name: 3, expecting 4\n",
      "WARNING: Entity <bound method Conv.call of <tensorflow.python.layers.convolutional.Conv2D object at 0x0000029C74BB4E48>> could not be transformed and will be executed as-is. Please report this to the AutgoGraph team. When filing the bug, set the verbosity to 10 (on Linux, `export AUTOGRAPH_VERBOSITY=10`) and attach the full output. Cause: converting <bound method Conv.call of <tensorflow.python.layers.convolutional.Conv2D object at 0x0000029C74BB4E48>>: AssertionError: Bad argument number for Name: 3, expecting 4\n",
      "WARNING:tensorflow:Entity <bound method Conv.call of <tensorflow.python.layers.convolutional.Conv2D object at 0x0000029C749D1088>> could not be transformed and will be executed as-is. Please report this to the AutgoGraph team. When filing the bug, set the verbosity to 10 (on Linux, `export AUTOGRAPH_VERBOSITY=10`) and attach the full output. Cause: converting <bound method Conv.call of <tensorflow.python.layers.convolutional.Conv2D object at 0x0000029C749D1088>>: AssertionError: Bad argument number for Name: 3, expecting 4\n"
     ]
    },
    {
     "name": "stdout",
     "output_type": "stream",
     "text": [
      "WARNING: Entity <bound method Conv.call of <tensorflow.python.layers.convolutional.Conv2D object at 0x0000029C749D1088>> could not be transformed and will be executed as-is. Please report this to the AutgoGraph team. When filing the bug, set the verbosity to 10 (on Linux, `export AUTOGRAPH_VERBOSITY=10`) and attach the full output. Cause: converting <bound method Conv.call of <tensorflow.python.layers.convolutional.Conv2D object at 0x0000029C749D1088>>: AssertionError: Bad argument number for Name: 3, expecting 4\n",
      "WARNING:tensorflow:Entity <bound method Conv.call of <tensorflow.python.layers.convolutional.Conv2D object at 0x0000029C749D1088>> could not be transformed and will be executed as-is. Please report this to the AutgoGraph team. When filing the bug, set the verbosity to 10 (on Linux, `export AUTOGRAPH_VERBOSITY=10`) and attach the full output. Cause: converting <bound method Conv.call of <tensorflow.python.layers.convolutional.Conv2D object at 0x0000029C749D1088>>: AssertionError: Bad argument number for Name: 3, expecting 4\n",
      "WARNING: Entity <bound method Conv.call of <tensorflow.python.layers.convolutional.Conv2D object at 0x0000029C749D1088>> could not be transformed and will be executed as-is. Please report this to the AutgoGraph team. When filing the bug, set the verbosity to 10 (on Linux, `export AUTOGRAPH_VERBOSITY=10`) and attach the full output. Cause: converting <bound method Conv.call of <tensorflow.python.layers.convolutional.Conv2D object at 0x0000029C749D1088>>: AssertionError: Bad argument number for Name: 3, expecting 4\n",
      "WARNING:tensorflow:Entity <bound method Conv.call of <tensorflow.python.layers.convolutional.Conv2D object at 0x0000029C749D1088>> could not be transformed and will be executed as-is. Please report this to the AutgoGraph team. When filing the bug, set the verbosity to 10 (on Linux, `export AUTOGRAPH_VERBOSITY=10`) and attach the full output. Cause: converting <bound method Conv.call of <tensorflow.python.layers.convolutional.Conv2D object at 0x0000029C749D1088>>: AssertionError: Bad argument number for Name: 3, expecting 4\n",
      "WARNING: Entity <bound method Conv.call of <tensorflow.python.layers.convolutional.Conv2D object at 0x0000029C749D1088>> could not be transformed and will be executed as-is. Please report this to the AutgoGraph team. When filing the bug, set the verbosity to 10 (on Linux, `export AUTOGRAPH_VERBOSITY=10`) and attach the full output. Cause: converting <bound method Conv.call of <tensorflow.python.layers.convolutional.Conv2D object at 0x0000029C749D1088>>: AssertionError: Bad argument number for Name: 3, expecting 4\n",
      "WARNING:tensorflow:Entity <bound method Conv.call of <tensorflow.python.layers.convolutional.Conv2D object at 0x0000029C712E6048>> could not be transformed and will be executed as-is. Please report this to the AutgoGraph team. When filing the bug, set the verbosity to 10 (on Linux, `export AUTOGRAPH_VERBOSITY=10`) and attach the full output. Cause: converting <bound method Conv.call of <tensorflow.python.layers.convolutional.Conv2D object at 0x0000029C712E6048>>: AssertionError: Bad argument number for Name: 3, expecting 4\n",
      "WARNING: Entity <bound method Conv.call of <tensorflow.python.layers.convolutional.Conv2D object at 0x0000029C712E6048>> could not be transformed and will be executed as-is. Please report this to the AutgoGraph team. When filing the bug, set the verbosity to 10 (on Linux, `export AUTOGRAPH_VERBOSITY=10`) and attach the full output. Cause: converting <bound method Conv.call of <tensorflow.python.layers.convolutional.Conv2D object at 0x0000029C712E6048>>: AssertionError: Bad argument number for Name: 3, expecting 4\n",
      "WARNING:tensorflow:Entity <bound method Conv.call of <tensorflow.python.layers.convolutional.Conv2D object at 0x0000029C749D1088>> could not be transformed and will be executed as-is. Please report this to the AutgoGraph team. When filing the bug, set the verbosity to 10 (on Linux, `export AUTOGRAPH_VERBOSITY=10`) and attach the full output. Cause: converting <bound method Conv.call of <tensorflow.python.layers.convolutional.Conv2D object at 0x0000029C749D1088>>: AssertionError: Bad argument number for Name: 3, expecting 4\n",
      "WARNING: Entity <bound method Conv.call of <tensorflow.python.layers.convolutional.Conv2D object at 0x0000029C749D1088>> could not be transformed and will be executed as-is. Please report this to the AutgoGraph team. When filing the bug, set the verbosity to 10 (on Linux, `export AUTOGRAPH_VERBOSITY=10`) and attach the full output. Cause: converting <bound method Conv.call of <tensorflow.python.layers.convolutional.Conv2D object at 0x0000029C749D1088>>: AssertionError: Bad argument number for Name: 3, expecting 4\n",
      "WARNING:tensorflow:Entity <bound method Conv.call of <tensorflow.python.layers.convolutional.Conv2D object at 0x0000029C74BB4E48>> could not be transformed and will be executed as-is. Please report this to the AutgoGraph team. When filing the bug, set the verbosity to 10 (on Linux, `export AUTOGRAPH_VERBOSITY=10`) and attach the full output. Cause: converting <bound method Conv.call of <tensorflow.python.layers.convolutional.Conv2D object at 0x0000029C74BB4E48>>: AssertionError: Bad argument number for Name: 3, expecting 4\n",
      "WARNING: Entity <bound method Conv.call of <tensorflow.python.layers.convolutional.Conv2D object at 0x0000029C74BB4E48>> could not be transformed and will be executed as-is. Please report this to the AutgoGraph team. When filing the bug, set the verbosity to 10 (on Linux, `export AUTOGRAPH_VERBOSITY=10`) and attach the full output. Cause: converting <bound method Conv.call of <tensorflow.python.layers.convolutional.Conv2D object at 0x0000029C74BB4E48>>: AssertionError: Bad argument number for Name: 3, expecting 4\n",
      "WARNING:tensorflow:Entity <bound method Conv.call of <tensorflow.python.layers.convolutional.Conv2D object at 0x0000029C712E6048>> could not be transformed and will be executed as-is. Please report this to the AutgoGraph team. When filing the bug, set the verbosity to 10 (on Linux, `export AUTOGRAPH_VERBOSITY=10`) and attach the full output. Cause: converting <bound method Conv.call of <tensorflow.python.layers.convolutional.Conv2D object at 0x0000029C712E6048>>: AssertionError: Bad argument number for Name: 3, expecting 4\n",
      "WARNING: Entity <bound method Conv.call of <tensorflow.python.layers.convolutional.Conv2D object at 0x0000029C712E6048>> could not be transformed and will be executed as-is. Please report this to the AutgoGraph team. When filing the bug, set the verbosity to 10 (on Linux, `export AUTOGRAPH_VERBOSITY=10`) and attach the full output. Cause: converting <bound method Conv.call of <tensorflow.python.layers.convolutional.Conv2D object at 0x0000029C712E6048>>: AssertionError: Bad argument number for Name: 3, expecting 4\n",
      "WARNING:tensorflow:Entity <bound method Conv.call of <tensorflow.python.layers.convolutional.Conv2D object at 0x0000029C74BB4E48>> could not be transformed and will be executed as-is. Please report this to the AutgoGraph team. When filing the bug, set the verbosity to 10 (on Linux, `export AUTOGRAPH_VERBOSITY=10`) and attach the full output. Cause: converting <bound method Conv.call of <tensorflow.python.layers.convolutional.Conv2D object at 0x0000029C74BB4E48>>: AssertionError: Bad argument number for Name: 3, expecting 4\n",
      "WARNING: Entity <bound method Conv.call of <tensorflow.python.layers.convolutional.Conv2D object at 0x0000029C74BB4E48>> could not be transformed and will be executed as-is. Please report this to the AutgoGraph team. When filing the bug, set the verbosity to 10 (on Linux, `export AUTOGRAPH_VERBOSITY=10`) and attach the full output. Cause: converting <bound method Conv.call of <tensorflow.python.layers.convolutional.Conv2D object at 0x0000029C74BB4E48>>: AssertionError: Bad argument number for Name: 3, expecting 4\n",
      "WARNING:tensorflow:Entity <bound method Conv.call of <tensorflow.python.layers.convolutional.Conv2D object at 0x0000029C712E6048>> could not be transformed and will be executed as-is. Please report this to the AutgoGraph team. When filing the bug, set the verbosity to 10 (on Linux, `export AUTOGRAPH_VERBOSITY=10`) and attach the full output. Cause: converting <bound method Conv.call of <tensorflow.python.layers.convolutional.Conv2D object at 0x0000029C712E6048>>: AssertionError: Bad argument number for Name: 3, expecting 4\n"
     ]
    },
    {
     "name": "stdout",
     "output_type": "stream",
     "text": [
      "WARNING: Entity <bound method Conv.call of <tensorflow.python.layers.convolutional.Conv2D object at 0x0000029C712E6048>> could not be transformed and will be executed as-is. Please report this to the AutgoGraph team. When filing the bug, set the verbosity to 10 (on Linux, `export AUTOGRAPH_VERBOSITY=10`) and attach the full output. Cause: converting <bound method Conv.call of <tensorflow.python.layers.convolutional.Conv2D object at 0x0000029C712E6048>>: AssertionError: Bad argument number for Name: 3, expecting 4\n",
      "WARNING:tensorflow:Entity <bound method Conv.call of <tensorflow.python.layers.convolutional.Conv2D object at 0x0000029C74BB4E48>> could not be transformed and will be executed as-is. Please report this to the AutgoGraph team. When filing the bug, set the verbosity to 10 (on Linux, `export AUTOGRAPH_VERBOSITY=10`) and attach the full output. Cause: converting <bound method Conv.call of <tensorflow.python.layers.convolutional.Conv2D object at 0x0000029C74BB4E48>>: AssertionError: Bad argument number for Name: 3, expecting 4\n",
      "WARNING: Entity <bound method Conv.call of <tensorflow.python.layers.convolutional.Conv2D object at 0x0000029C74BB4E48>> could not be transformed and will be executed as-is. Please report this to the AutgoGraph team. When filing the bug, set the verbosity to 10 (on Linux, `export AUTOGRAPH_VERBOSITY=10`) and attach the full output. Cause: converting <bound method Conv.call of <tensorflow.python.layers.convolutional.Conv2D object at 0x0000029C74BB4E48>>: AssertionError: Bad argument number for Name: 3, expecting 4\n",
      "WARNING:tensorflow:Entity <bound method Conv.call of <tensorflow.python.layers.convolutional.Conv2D object at 0x0000029C712E6048>> could not be transformed and will be executed as-is. Please report this to the AutgoGraph team. When filing the bug, set the verbosity to 10 (on Linux, `export AUTOGRAPH_VERBOSITY=10`) and attach the full output. Cause: converting <bound method Conv.call of <tensorflow.python.layers.convolutional.Conv2D object at 0x0000029C712E6048>>: AssertionError: Bad argument number for Name: 3, expecting 4\n",
      "WARNING: Entity <bound method Conv.call of <tensorflow.python.layers.convolutional.Conv2D object at 0x0000029C712E6048>> could not be transformed and will be executed as-is. Please report this to the AutgoGraph team. When filing the bug, set the verbosity to 10 (on Linux, `export AUTOGRAPH_VERBOSITY=10`) and attach the full output. Cause: converting <bound method Conv.call of <tensorflow.python.layers.convolutional.Conv2D object at 0x0000029C712E6048>>: AssertionError: Bad argument number for Name: 3, expecting 4\n",
      "WARNING:tensorflow:Entity <bound method Conv.call of <tensorflow.python.layers.convolutional.Conv2D object at 0x0000029C74BB4E48>> could not be transformed and will be executed as-is. Please report this to the AutgoGraph team. When filing the bug, set the verbosity to 10 (on Linux, `export AUTOGRAPH_VERBOSITY=10`) and attach the full output. Cause: converting <bound method Conv.call of <tensorflow.python.layers.convolutional.Conv2D object at 0x0000029C74BB4E48>>: AssertionError: Bad argument number for Name: 3, expecting 4\n",
      "WARNING: Entity <bound method Conv.call of <tensorflow.python.layers.convolutional.Conv2D object at 0x0000029C74BB4E48>> could not be transformed and will be executed as-is. Please report this to the AutgoGraph team. When filing the bug, set the verbosity to 10 (on Linux, `export AUTOGRAPH_VERBOSITY=10`) and attach the full output. Cause: converting <bound method Conv.call of <tensorflow.python.layers.convolutional.Conv2D object at 0x0000029C74BB4E48>>: AssertionError: Bad argument number for Name: 3, expecting 4\n",
      "WARNING:tensorflow:Entity <bound method Conv.call of <tensorflow.python.layers.convolutional.Conv2D object at 0x0000029C712E6048>> could not be transformed and will be executed as-is. Please report this to the AutgoGraph team. When filing the bug, set the verbosity to 10 (on Linux, `export AUTOGRAPH_VERBOSITY=10`) and attach the full output. Cause: converting <bound method Conv.call of <tensorflow.python.layers.convolutional.Conv2D object at 0x0000029C712E6048>>: AssertionError: Bad argument number for Name: 3, expecting 4\n",
      "WARNING: Entity <bound method Conv.call of <tensorflow.python.layers.convolutional.Conv2D object at 0x0000029C712E6048>> could not be transformed and will be executed as-is. Please report this to the AutgoGraph team. When filing the bug, set the verbosity to 10 (on Linux, `export AUTOGRAPH_VERBOSITY=10`) and attach the full output. Cause: converting <bound method Conv.call of <tensorflow.python.layers.convolutional.Conv2D object at 0x0000029C712E6048>>: AssertionError: Bad argument number for Name: 3, expecting 4\n",
      "WARNING:tensorflow:Entity <bound method Conv.call of <tensorflow.python.layers.convolutional.Conv2D object at 0x0000029C74BB4E48>> could not be transformed and will be executed as-is. Please report this to the AutgoGraph team. When filing the bug, set the verbosity to 10 (on Linux, `export AUTOGRAPH_VERBOSITY=10`) and attach the full output. Cause: converting <bound method Conv.call of <tensorflow.python.layers.convolutional.Conv2D object at 0x0000029C74BB4E48>>: AssertionError: Bad argument number for Name: 3, expecting 4\n",
      "WARNING: Entity <bound method Conv.call of <tensorflow.python.layers.convolutional.Conv2D object at 0x0000029C74BB4E48>> could not be transformed and will be executed as-is. Please report this to the AutgoGraph team. When filing the bug, set the verbosity to 10 (on Linux, `export AUTOGRAPH_VERBOSITY=10`) and attach the full output. Cause: converting <bound method Conv.call of <tensorflow.python.layers.convolutional.Conv2D object at 0x0000029C74BB4E48>>: AssertionError: Bad argument number for Name: 3, expecting 4\n",
      "WARNING:tensorflow:Entity <bound method Conv.call of <tensorflow.python.layers.convolutional.Conv2D object at 0x0000029C712E6048>> could not be transformed and will be executed as-is. Please report this to the AutgoGraph team. When filing the bug, set the verbosity to 10 (on Linux, `export AUTOGRAPH_VERBOSITY=10`) and attach the full output. Cause: converting <bound method Conv.call of <tensorflow.python.layers.convolutional.Conv2D object at 0x0000029C712E6048>>: AssertionError: Bad argument number for Name: 3, expecting 4\n",
      "WARNING: Entity <bound method Conv.call of <tensorflow.python.layers.convolutional.Conv2D object at 0x0000029C712E6048>> could not be transformed and will be executed as-is. Please report this to the AutgoGraph team. When filing the bug, set the verbosity to 10 (on Linux, `export AUTOGRAPH_VERBOSITY=10`) and attach the full output. Cause: converting <bound method Conv.call of <tensorflow.python.layers.convolutional.Conv2D object at 0x0000029C712E6048>>: AssertionError: Bad argument number for Name: 3, expecting 4\n",
      "WARNING:tensorflow:Entity <bound method Conv.call of <tensorflow.python.layers.convolutional.Conv2D object at 0x0000029C74BB4E48>> could not be transformed and will be executed as-is. Please report this to the AutgoGraph team. When filing the bug, set the verbosity to 10 (on Linux, `export AUTOGRAPH_VERBOSITY=10`) and attach the full output. Cause: converting <bound method Conv.call of <tensorflow.python.layers.convolutional.Conv2D object at 0x0000029C74BB4E48>>: AssertionError: Bad argument number for Name: 3, expecting 4\n",
      "WARNING: Entity <bound method Conv.call of <tensorflow.python.layers.convolutional.Conv2D object at 0x0000029C74BB4E48>> could not be transformed and will be executed as-is. Please report this to the AutgoGraph team. When filing the bug, set the verbosity to 10 (on Linux, `export AUTOGRAPH_VERBOSITY=10`) and attach the full output. Cause: converting <bound method Conv.call of <tensorflow.python.layers.convolutional.Conv2D object at 0x0000029C74BB4E48>>: AssertionError: Bad argument number for Name: 3, expecting 4\n",
      "WARNING:tensorflow:Entity <bound method Conv.call of <tensorflow.python.layers.convolutional.Conv2D object at 0x0000029C712E6048>> could not be transformed and will be executed as-is. Please report this to the AutgoGraph team. When filing the bug, set the verbosity to 10 (on Linux, `export AUTOGRAPH_VERBOSITY=10`) and attach the full output. Cause: converting <bound method Conv.call of <tensorflow.python.layers.convolutional.Conv2D object at 0x0000029C712E6048>>: AssertionError: Bad argument number for Name: 3, expecting 4\n"
     ]
    },
    {
     "name": "stdout",
     "output_type": "stream",
     "text": [
      "WARNING: Entity <bound method Conv.call of <tensorflow.python.layers.convolutional.Conv2D object at 0x0000029C712E6048>> could not be transformed and will be executed as-is. Please report this to the AutgoGraph team. When filing the bug, set the verbosity to 10 (on Linux, `export AUTOGRAPH_VERBOSITY=10`) and attach the full output. Cause: converting <bound method Conv.call of <tensorflow.python.layers.convolutional.Conv2D object at 0x0000029C712E6048>>: AssertionError: Bad argument number for Name: 3, expecting 4\n",
      "WARNING:tensorflow:Entity <bound method Conv.call of <tensorflow.python.layers.convolutional.Conv2D object at 0x0000029C74BB4E48>> could not be transformed and will be executed as-is. Please report this to the AutgoGraph team. When filing the bug, set the verbosity to 10 (on Linux, `export AUTOGRAPH_VERBOSITY=10`) and attach the full output. Cause: converting <bound method Conv.call of <tensorflow.python.layers.convolutional.Conv2D object at 0x0000029C74BB4E48>>: AssertionError: Bad argument number for Name: 3, expecting 4\n",
      "WARNING: Entity <bound method Conv.call of <tensorflow.python.layers.convolutional.Conv2D object at 0x0000029C74BB4E48>> could not be transformed and will be executed as-is. Please report this to the AutgoGraph team. When filing the bug, set the verbosity to 10 (on Linux, `export AUTOGRAPH_VERBOSITY=10`) and attach the full output. Cause: converting <bound method Conv.call of <tensorflow.python.layers.convolutional.Conv2D object at 0x0000029C74BB4E48>>: AssertionError: Bad argument number for Name: 3, expecting 4\n",
      "WARNING:tensorflow:Entity <bound method Conv.call of <tensorflow.python.layers.convolutional.Conv2D object at 0x0000029C712E6048>> could not be transformed and will be executed as-is. Please report this to the AutgoGraph team. When filing the bug, set the verbosity to 10 (on Linux, `export AUTOGRAPH_VERBOSITY=10`) and attach the full output. Cause: converting <bound method Conv.call of <tensorflow.python.layers.convolutional.Conv2D object at 0x0000029C712E6048>>: AssertionError: Bad argument number for Name: 3, expecting 4\n",
      "WARNING: Entity <bound method Conv.call of <tensorflow.python.layers.convolutional.Conv2D object at 0x0000029C712E6048>> could not be transformed and will be executed as-is. Please report this to the AutgoGraph team. When filing the bug, set the verbosity to 10 (on Linux, `export AUTOGRAPH_VERBOSITY=10`) and attach the full output. Cause: converting <bound method Conv.call of <tensorflow.python.layers.convolutional.Conv2D object at 0x0000029C712E6048>>: AssertionError: Bad argument number for Name: 3, expecting 4\n",
      "WARNING:tensorflow:Entity <bound method Conv.call of <tensorflow.python.layers.convolutional.Conv2D object at 0x0000029C74BB4E48>> could not be transformed and will be executed as-is. Please report this to the AutgoGraph team. When filing the bug, set the verbosity to 10 (on Linux, `export AUTOGRAPH_VERBOSITY=10`) and attach the full output. Cause: converting <bound method Conv.call of <tensorflow.python.layers.convolutional.Conv2D object at 0x0000029C74BB4E48>>: AssertionError: Bad argument number for Name: 3, expecting 4\n",
      "WARNING: Entity <bound method Conv.call of <tensorflow.python.layers.convolutional.Conv2D object at 0x0000029C74BB4E48>> could not be transformed and will be executed as-is. Please report this to the AutgoGraph team. When filing the bug, set the verbosity to 10 (on Linux, `export AUTOGRAPH_VERBOSITY=10`) and attach the full output. Cause: converting <bound method Conv.call of <tensorflow.python.layers.convolutional.Conv2D object at 0x0000029C74BB4E48>>: AssertionError: Bad argument number for Name: 3, expecting 4\n",
      "WARNING:tensorflow:Entity <bound method Conv.call of <tensorflow.python.layers.convolutional.Conv2D object at 0x0000029C712E6048>> could not be transformed and will be executed as-is. Please report this to the AutgoGraph team. When filing the bug, set the verbosity to 10 (on Linux, `export AUTOGRAPH_VERBOSITY=10`) and attach the full output. Cause: converting <bound method Conv.call of <tensorflow.python.layers.convolutional.Conv2D object at 0x0000029C712E6048>>: AssertionError: Bad argument number for Name: 3, expecting 4\n",
      "WARNING: Entity <bound method Conv.call of <tensorflow.python.layers.convolutional.Conv2D object at 0x0000029C712E6048>> could not be transformed and will be executed as-is. Please report this to the AutgoGraph team. When filing the bug, set the verbosity to 10 (on Linux, `export AUTOGRAPH_VERBOSITY=10`) and attach the full output. Cause: converting <bound method Conv.call of <tensorflow.python.layers.convolutional.Conv2D object at 0x0000029C712E6048>>: AssertionError: Bad argument number for Name: 3, expecting 4\n",
      "WARNING:tensorflow:Entity <bound method Conv.call of <tensorflow.python.layers.convolutional.Conv2D object at 0x0000029C74BB4E48>> could not be transformed and will be executed as-is. Please report this to the AutgoGraph team. When filing the bug, set the verbosity to 10 (on Linux, `export AUTOGRAPH_VERBOSITY=10`) and attach the full output. Cause: converting <bound method Conv.call of <tensorflow.python.layers.convolutional.Conv2D object at 0x0000029C74BB4E48>>: AssertionError: Bad argument number for Name: 3, expecting 4\n",
      "WARNING: Entity <bound method Conv.call of <tensorflow.python.layers.convolutional.Conv2D object at 0x0000029C74BB4E48>> could not be transformed and will be executed as-is. Please report this to the AutgoGraph team. When filing the bug, set the verbosity to 10 (on Linux, `export AUTOGRAPH_VERBOSITY=10`) and attach the full output. Cause: converting <bound method Conv.call of <tensorflow.python.layers.convolutional.Conv2D object at 0x0000029C74BB4E48>>: AssertionError: Bad argument number for Name: 3, expecting 4\n",
      "WARNING:tensorflow:Entity <bound method Conv.call of <tensorflow.python.layers.convolutional.Conv2D object at 0x0000029C712E6048>> could not be transformed and will be executed as-is. Please report this to the AutgoGraph team. When filing the bug, set the verbosity to 10 (on Linux, `export AUTOGRAPH_VERBOSITY=10`) and attach the full output. Cause: converting <bound method Conv.call of <tensorflow.python.layers.convolutional.Conv2D object at 0x0000029C712E6048>>: AssertionError: Bad argument number for Name: 3, expecting 4\n",
      "WARNING: Entity <bound method Conv.call of <tensorflow.python.layers.convolutional.Conv2D object at 0x0000029C712E6048>> could not be transformed and will be executed as-is. Please report this to the AutgoGraph team. When filing the bug, set the verbosity to 10 (on Linux, `export AUTOGRAPH_VERBOSITY=10`) and attach the full output. Cause: converting <bound method Conv.call of <tensorflow.python.layers.convolutional.Conv2D object at 0x0000029C712E6048>>: AssertionError: Bad argument number for Name: 3, expecting 4\n",
      "WARNING:tensorflow:Entity <bound method Conv.call of <tensorflow.python.layers.convolutional.Conv2D object at 0x0000029C74BB4E48>> could not be transformed and will be executed as-is. Please report this to the AutgoGraph team. When filing the bug, set the verbosity to 10 (on Linux, `export AUTOGRAPH_VERBOSITY=10`) and attach the full output. Cause: converting <bound method Conv.call of <tensorflow.python.layers.convolutional.Conv2D object at 0x0000029C74BB4E48>>: AssertionError: Bad argument number for Name: 3, expecting 4\n",
      "WARNING: Entity <bound method Conv.call of <tensorflow.python.layers.convolutional.Conv2D object at 0x0000029C74BB4E48>> could not be transformed and will be executed as-is. Please report this to the AutgoGraph team. When filing the bug, set the verbosity to 10 (on Linux, `export AUTOGRAPH_VERBOSITY=10`) and attach the full output. Cause: converting <bound method Conv.call of <tensorflow.python.layers.convolutional.Conv2D object at 0x0000029C74BB4E48>>: AssertionError: Bad argument number for Name: 3, expecting 4\n",
      "WARNING:tensorflow:Entity <bound method Conv.call of <tensorflow.python.layers.convolutional.Conv2D object at 0x0000029C712E6048>> could not be transformed and will be executed as-is. Please report this to the AutgoGraph team. When filing the bug, set the verbosity to 10 (on Linux, `export AUTOGRAPH_VERBOSITY=10`) and attach the full output. Cause: converting <bound method Conv.call of <tensorflow.python.layers.convolutional.Conv2D object at 0x0000029C712E6048>>: AssertionError: Bad argument number for Name: 3, expecting 4\n"
     ]
    },
    {
     "name": "stdout",
     "output_type": "stream",
     "text": [
      "WARNING: Entity <bound method Conv.call of <tensorflow.python.layers.convolutional.Conv2D object at 0x0000029C712E6048>> could not be transformed and will be executed as-is. Please report this to the AutgoGraph team. When filing the bug, set the verbosity to 10 (on Linux, `export AUTOGRAPH_VERBOSITY=10`) and attach the full output. Cause: converting <bound method Conv.call of <tensorflow.python.layers.convolutional.Conv2D object at 0x0000029C712E6048>>: AssertionError: Bad argument number for Name: 3, expecting 4\n",
      "WARNING:tensorflow:Entity <bound method Conv.call of <tensorflow.python.layers.convolutional.Conv2D object at 0x0000029C74BB4E48>> could not be transformed and will be executed as-is. Please report this to the AutgoGraph team. When filing the bug, set the verbosity to 10 (on Linux, `export AUTOGRAPH_VERBOSITY=10`) and attach the full output. Cause: converting <bound method Conv.call of <tensorflow.python.layers.convolutional.Conv2D object at 0x0000029C74BB4E48>>: AssertionError: Bad argument number for Name: 3, expecting 4\n",
      "WARNING: Entity <bound method Conv.call of <tensorflow.python.layers.convolutional.Conv2D object at 0x0000029C74BB4E48>> could not be transformed and will be executed as-is. Please report this to the AutgoGraph team. When filing the bug, set the verbosity to 10 (on Linux, `export AUTOGRAPH_VERBOSITY=10`) and attach the full output. Cause: converting <bound method Conv.call of <tensorflow.python.layers.convolutional.Conv2D object at 0x0000029C74BB4E48>>: AssertionError: Bad argument number for Name: 3, expecting 4\n",
      "WARNING:tensorflow:Entity <bound method Conv.call of <tensorflow.python.layers.convolutional.Conv2D object at 0x0000029C712E6048>> could not be transformed and will be executed as-is. Please report this to the AutgoGraph team. When filing the bug, set the verbosity to 10 (on Linux, `export AUTOGRAPH_VERBOSITY=10`) and attach the full output. Cause: converting <bound method Conv.call of <tensorflow.python.layers.convolutional.Conv2D object at 0x0000029C712E6048>>: AssertionError: Bad argument number for Name: 3, expecting 4\n",
      "WARNING: Entity <bound method Conv.call of <tensorflow.python.layers.convolutional.Conv2D object at 0x0000029C712E6048>> could not be transformed and will be executed as-is. Please report this to the AutgoGraph team. When filing the bug, set the verbosity to 10 (on Linux, `export AUTOGRAPH_VERBOSITY=10`) and attach the full output. Cause: converting <bound method Conv.call of <tensorflow.python.layers.convolutional.Conv2D object at 0x0000029C712E6048>>: AssertionError: Bad argument number for Name: 3, expecting 4\n",
      "WARNING:tensorflow:Entity <bound method Conv.call of <tensorflow.python.layers.convolutional.Conv2D object at 0x0000029C74BB4E48>> could not be transformed and will be executed as-is. Please report this to the AutgoGraph team. When filing the bug, set the verbosity to 10 (on Linux, `export AUTOGRAPH_VERBOSITY=10`) and attach the full output. Cause: converting <bound method Conv.call of <tensorflow.python.layers.convolutional.Conv2D object at 0x0000029C74BB4E48>>: AssertionError: Bad argument number for Name: 3, expecting 4\n",
      "WARNING: Entity <bound method Conv.call of <tensorflow.python.layers.convolutional.Conv2D object at 0x0000029C74BB4E48>> could not be transformed and will be executed as-is. Please report this to the AutgoGraph team. When filing the bug, set the verbosity to 10 (on Linux, `export AUTOGRAPH_VERBOSITY=10`) and attach the full output. Cause: converting <bound method Conv.call of <tensorflow.python.layers.convolutional.Conv2D object at 0x0000029C74BB4E48>>: AssertionError: Bad argument number for Name: 3, expecting 4\n",
      "WARNING:tensorflow:Entity <bound method Conv.call of <tensorflow.python.layers.convolutional.Conv2D object at 0x0000029C74FD0048>> could not be transformed and will be executed as-is. Please report this to the AutgoGraph team. When filing the bug, set the verbosity to 10 (on Linux, `export AUTOGRAPH_VERBOSITY=10`) and attach the full output. Cause: converting <bound method Conv.call of <tensorflow.python.layers.convolutional.Conv2D object at 0x0000029C74FD0048>>: AssertionError: Bad argument number for Name: 3, expecting 4\n",
      "WARNING: Entity <bound method Conv.call of <tensorflow.python.layers.convolutional.Conv2D object at 0x0000029C74FD0048>> could not be transformed and will be executed as-is. Please report this to the AutgoGraph team. When filing the bug, set the verbosity to 10 (on Linux, `export AUTOGRAPH_VERBOSITY=10`) and attach the full output. Cause: converting <bound method Conv.call of <tensorflow.python.layers.convolutional.Conv2D object at 0x0000029C74FD0048>>: AssertionError: Bad argument number for Name: 3, expecting 4\n",
      "WARNING:tensorflow:Entity <bound method Pooling2D.call of <tensorflow.python.layers.pooling.MaxPooling2D object at 0x0000029C742D4B48>> could not be transformed and will be executed as-is. Please report this to the AutgoGraph team. When filing the bug, set the verbosity to 10 (on Linux, `export AUTOGRAPH_VERBOSITY=10`) and attach the full output. Cause: converting <bound method Pooling2D.call of <tensorflow.python.layers.pooling.MaxPooling2D object at 0x0000029C742D4B48>>: AssertionError: Bad argument number for Name: 3, expecting 4\n",
      "WARNING: Entity <bound method Pooling2D.call of <tensorflow.python.layers.pooling.MaxPooling2D object at 0x0000029C742D4B48>> could not be transformed and will be executed as-is. Please report this to the AutgoGraph team. When filing the bug, set the verbosity to 10 (on Linux, `export AUTOGRAPH_VERBOSITY=10`) and attach the full output. Cause: converting <bound method Pooling2D.call of <tensorflow.python.layers.pooling.MaxPooling2D object at 0x0000029C742D4B48>>: AssertionError: Bad argument number for Name: 3, expecting 4\n",
      "WARNING:tensorflow:Entity <bound method Conv.call of <tensorflow.python.layers.convolutional.Conv2D object at 0x0000029C751B4D88>> could not be transformed and will be executed as-is. Please report this to the AutgoGraph team. When filing the bug, set the verbosity to 10 (on Linux, `export AUTOGRAPH_VERBOSITY=10`) and attach the full output. Cause: converting <bound method Conv.call of <tensorflow.python.layers.convolutional.Conv2D object at 0x0000029C751B4D88>>: AssertionError: Bad argument number for Name: 3, expecting 4\n",
      "WARNING: Entity <bound method Conv.call of <tensorflow.python.layers.convolutional.Conv2D object at 0x0000029C751B4D88>> could not be transformed and will be executed as-is. Please report this to the AutgoGraph team. When filing the bug, set the verbosity to 10 (on Linux, `export AUTOGRAPH_VERBOSITY=10`) and attach the full output. Cause: converting <bound method Conv.call of <tensorflow.python.layers.convolutional.Conv2D object at 0x0000029C751B4D88>>: AssertionError: Bad argument number for Name: 3, expecting 4\n",
      "WARNING:tensorflow:Entity <bound method Conv.call of <tensorflow.python.layers.convolutional.Conv2D object at 0x0000029C75240648>> could not be transformed and will be executed as-is. Please report this to the AutgoGraph team. When filing the bug, set the verbosity to 10 (on Linux, `export AUTOGRAPH_VERBOSITY=10`) and attach the full output. Cause: converting <bound method Conv.call of <tensorflow.python.layers.convolutional.Conv2D object at 0x0000029C75240648>>: AssertionError: Bad argument number for Name: 3, expecting 4\n",
      "WARNING: Entity <bound method Conv.call of <tensorflow.python.layers.convolutional.Conv2D object at 0x0000029C75240648>> could not be transformed and will be executed as-is. Please report this to the AutgoGraph team. When filing the bug, set the verbosity to 10 (on Linux, `export AUTOGRAPH_VERBOSITY=10`) and attach the full output. Cause: converting <bound method Conv.call of <tensorflow.python.layers.convolutional.Conv2D object at 0x0000029C75240648>>: AssertionError: Bad argument number for Name: 3, expecting 4\n",
      "WARNING:tensorflow:Entity <bound method Conv.call of <tensorflow.python.layers.convolutional.Conv2D object at 0x0000029C75240648>> could not be transformed and will be executed as-is. Please report this to the AutgoGraph team. When filing the bug, set the verbosity to 10 (on Linux, `export AUTOGRAPH_VERBOSITY=10`) and attach the full output. Cause: converting <bound method Conv.call of <tensorflow.python.layers.convolutional.Conv2D object at 0x0000029C75240648>>: AssertionError: Bad argument number for Name: 3, expecting 4\n"
     ]
    },
    {
     "name": "stdout",
     "output_type": "stream",
     "text": [
      "WARNING: Entity <bound method Conv.call of <tensorflow.python.layers.convolutional.Conv2D object at 0x0000029C75240648>> could not be transformed and will be executed as-is. Please report this to the AutgoGraph team. When filing the bug, set the verbosity to 10 (on Linux, `export AUTOGRAPH_VERBOSITY=10`) and attach the full output. Cause: converting <bound method Conv.call of <tensorflow.python.layers.convolutional.Conv2D object at 0x0000029C75240648>>: AssertionError: Bad argument number for Name: 3, expecting 4\n",
      "WARNING:tensorflow:Entity <bound method Conv.call of <tensorflow.python.layers.convolutional.Conv2D object at 0x0000029C751D51C8>> could not be transformed and will be executed as-is. Please report this to the AutgoGraph team. When filing the bug, set the verbosity to 10 (on Linux, `export AUTOGRAPH_VERBOSITY=10`) and attach the full output. Cause: converting <bound method Conv.call of <tensorflow.python.layers.convolutional.Conv2D object at 0x0000029C751D51C8>>: AssertionError: Bad argument number for Name: 3, expecting 4\n",
      "WARNING: Entity <bound method Conv.call of <tensorflow.python.layers.convolutional.Conv2D object at 0x0000029C751D51C8>> could not be transformed and will be executed as-is. Please report this to the AutgoGraph team. When filing the bug, set the verbosity to 10 (on Linux, `export AUTOGRAPH_VERBOSITY=10`) and attach the full output. Cause: converting <bound method Conv.call of <tensorflow.python.layers.convolutional.Conv2D object at 0x0000029C751D51C8>>: AssertionError: Bad argument number for Name: 3, expecting 4\n",
      "WARNING:tensorflow:Entity <bound method Conv.call of <tensorflow.python.layers.convolutional.Conv2D object at 0x0000029C75240648>> could not be transformed and will be executed as-is. Please report this to the AutgoGraph team. When filing the bug, set the verbosity to 10 (on Linux, `export AUTOGRAPH_VERBOSITY=10`) and attach the full output. Cause: converting <bound method Conv.call of <tensorflow.python.layers.convolutional.Conv2D object at 0x0000029C75240648>>: AssertionError: Bad argument number for Name: 3, expecting 4\n",
      "WARNING: Entity <bound method Conv.call of <tensorflow.python.layers.convolutional.Conv2D object at 0x0000029C75240648>> could not be transformed and will be executed as-is. Please report this to the AutgoGraph team. When filing the bug, set the verbosity to 10 (on Linux, `export AUTOGRAPH_VERBOSITY=10`) and attach the full output. Cause: converting <bound method Conv.call of <tensorflow.python.layers.convolutional.Conv2D object at 0x0000029C75240648>>: AssertionError: Bad argument number for Name: 3, expecting 4\n",
      "WARNING:tensorflow:Entity <bound method Conv.call of <tensorflow.python.layers.convolutional.Conv2D object at 0x0000029C75240648>> could not be transformed and will be executed as-is. Please report this to the AutgoGraph team. When filing the bug, set the verbosity to 10 (on Linux, `export AUTOGRAPH_VERBOSITY=10`) and attach the full output. Cause: converting <bound method Conv.call of <tensorflow.python.layers.convolutional.Conv2D object at 0x0000029C75240648>>: AssertionError: Bad argument number for Name: 3, expecting 4\n",
      "WARNING: Entity <bound method Conv.call of <tensorflow.python.layers.convolutional.Conv2D object at 0x0000029C75240648>> could not be transformed and will be executed as-is. Please report this to the AutgoGraph team. When filing the bug, set the verbosity to 10 (on Linux, `export AUTOGRAPH_VERBOSITY=10`) and attach the full output. Cause: converting <bound method Conv.call of <tensorflow.python.layers.convolutional.Conv2D object at 0x0000029C75240648>>: AssertionError: Bad argument number for Name: 3, expecting 4\n",
      "WARNING:tensorflow:Entity <bound method Conv.call of <tensorflow.python.layers.convolutional.Conv2D object at 0x0000029C75240648>> could not be transformed and will be executed as-is. Please report this to the AutgoGraph team. When filing the bug, set the verbosity to 10 (on Linux, `export AUTOGRAPH_VERBOSITY=10`) and attach the full output. Cause: converting <bound method Conv.call of <tensorflow.python.layers.convolutional.Conv2D object at 0x0000029C75240648>>: AssertionError: Bad argument number for Name: 3, expecting 4\n",
      "WARNING: Entity <bound method Conv.call of <tensorflow.python.layers.convolutional.Conv2D object at 0x0000029C75240648>> could not be transformed and will be executed as-is. Please report this to the AutgoGraph team. When filing the bug, set the verbosity to 10 (on Linux, `export AUTOGRAPH_VERBOSITY=10`) and attach the full output. Cause: converting <bound method Conv.call of <tensorflow.python.layers.convolutional.Conv2D object at 0x0000029C75240648>>: AssertionError: Bad argument number for Name: 3, expecting 4\n",
      "WARNING:tensorflow:Entity <bound method Conv.call of <tensorflow.python.layers.convolutional.Conv2D object at 0x0000029C74F98D88>> could not be transformed and will be executed as-is. Please report this to the AutgoGraph team. When filing the bug, set the verbosity to 10 (on Linux, `export AUTOGRAPH_VERBOSITY=10`) and attach the full output. Cause: converting <bound method Conv.call of <tensorflow.python.layers.convolutional.Conv2D object at 0x0000029C74F98D88>>: AssertionError: Bad argument number for Name: 3, expecting 4\n",
      "WARNING: Entity <bound method Conv.call of <tensorflow.python.layers.convolutional.Conv2D object at 0x0000029C74F98D88>> could not be transformed and will be executed as-is. Please report this to the AutgoGraph team. When filing the bug, set the verbosity to 10 (on Linux, `export AUTOGRAPH_VERBOSITY=10`) and attach the full output. Cause: converting <bound method Conv.call of <tensorflow.python.layers.convolutional.Conv2D object at 0x0000029C74F98D88>>: AssertionError: Bad argument number for Name: 3, expecting 4\n",
      "WARNING:tensorflow:Entity <bound method Conv.call of <tensorflow.python.layers.convolutional.Conv2D object at 0x0000029C75240648>> could not be transformed and will be executed as-is. Please report this to the AutgoGraph team. When filing the bug, set the verbosity to 10 (on Linux, `export AUTOGRAPH_VERBOSITY=10`) and attach the full output. Cause: converting <bound method Conv.call of <tensorflow.python.layers.convolutional.Conv2D object at 0x0000029C75240648>>: AssertionError: Bad argument number for Name: 3, expecting 4\n",
      "WARNING: Entity <bound method Conv.call of <tensorflow.python.layers.convolutional.Conv2D object at 0x0000029C75240648>> could not be transformed and will be executed as-is. Please report this to the AutgoGraph team. When filing the bug, set the verbosity to 10 (on Linux, `export AUTOGRAPH_VERBOSITY=10`) and attach the full output. Cause: converting <bound method Conv.call of <tensorflow.python.layers.convolutional.Conv2D object at 0x0000029C75240648>>: AssertionError: Bad argument number for Name: 3, expecting 4\n",
      "WARNING:tensorflow:Entity <bound method Conv.call of <tensorflow.python.layers.convolutional.Conv2D object at 0x0000029C751D51C8>> could not be transformed and will be executed as-is. Please report this to the AutgoGraph team. When filing the bug, set the verbosity to 10 (on Linux, `export AUTOGRAPH_VERBOSITY=10`) and attach the full output. Cause: converting <bound method Conv.call of <tensorflow.python.layers.convolutional.Conv2D object at 0x0000029C751D51C8>>: AssertionError: Bad argument number for Name: 3, expecting 4\n",
      "WARNING: Entity <bound method Conv.call of <tensorflow.python.layers.convolutional.Conv2D object at 0x0000029C751D51C8>> could not be transformed and will be executed as-is. Please report this to the AutgoGraph team. When filing the bug, set the verbosity to 10 (on Linux, `export AUTOGRAPH_VERBOSITY=10`) and attach the full output. Cause: converting <bound method Conv.call of <tensorflow.python.layers.convolutional.Conv2D object at 0x0000029C751D51C8>>: AssertionError: Bad argument number for Name: 3, expecting 4\n",
      "WARNING:tensorflow:Entity <bound method Conv.call of <tensorflow.python.layers.convolutional.Conv2D object at 0x0000029C74F98D88>> could not be transformed and will be executed as-is. Please report this to the AutgoGraph team. When filing the bug, set the verbosity to 10 (on Linux, `export AUTOGRAPH_VERBOSITY=10`) and attach the full output. Cause: converting <bound method Conv.call of <tensorflow.python.layers.convolutional.Conv2D object at 0x0000029C74F98D88>>: AssertionError: Bad argument number for Name: 3, expecting 4\n"
     ]
    },
    {
     "name": "stdout",
     "output_type": "stream",
     "text": [
      "WARNING: Entity <bound method Conv.call of <tensorflow.python.layers.convolutional.Conv2D object at 0x0000029C74F98D88>> could not be transformed and will be executed as-is. Please report this to the AutgoGraph team. When filing the bug, set the verbosity to 10 (on Linux, `export AUTOGRAPH_VERBOSITY=10`) and attach the full output. Cause: converting <bound method Conv.call of <tensorflow.python.layers.convolutional.Conv2D object at 0x0000029C74F98D88>>: AssertionError: Bad argument number for Name: 3, expecting 4\n",
      "WARNING:tensorflow:Entity <bound method Conv.call of <tensorflow.python.layers.convolutional.Conv2D object at 0x0000029C751D51C8>> could not be transformed and will be executed as-is. Please report this to the AutgoGraph team. When filing the bug, set the verbosity to 10 (on Linux, `export AUTOGRAPH_VERBOSITY=10`) and attach the full output. Cause: converting <bound method Conv.call of <tensorflow.python.layers.convolutional.Conv2D object at 0x0000029C751D51C8>>: AssertionError: Bad argument number for Name: 3, expecting 4\n",
      "WARNING: Entity <bound method Conv.call of <tensorflow.python.layers.convolutional.Conv2D object at 0x0000029C751D51C8>> could not be transformed and will be executed as-is. Please report this to the AutgoGraph team. When filing the bug, set the verbosity to 10 (on Linux, `export AUTOGRAPH_VERBOSITY=10`) and attach the full output. Cause: converting <bound method Conv.call of <tensorflow.python.layers.convolutional.Conv2D object at 0x0000029C751D51C8>>: AssertionError: Bad argument number for Name: 3, expecting 4\n",
      "WARNING:tensorflow:Entity <bound method Conv.call of <tensorflow.python.layers.convolutional.Conv2D object at 0x0000029C74F98D88>> could not be transformed and will be executed as-is. Please report this to the AutgoGraph team. When filing the bug, set the verbosity to 10 (on Linux, `export AUTOGRAPH_VERBOSITY=10`) and attach the full output. Cause: converting <bound method Conv.call of <tensorflow.python.layers.convolutional.Conv2D object at 0x0000029C74F98D88>>: AssertionError: Bad argument number for Name: 3, expecting 4\n",
      "WARNING: Entity <bound method Conv.call of <tensorflow.python.layers.convolutional.Conv2D object at 0x0000029C74F98D88>> could not be transformed and will be executed as-is. Please report this to the AutgoGraph team. When filing the bug, set the verbosity to 10 (on Linux, `export AUTOGRAPH_VERBOSITY=10`) and attach the full output. Cause: converting <bound method Conv.call of <tensorflow.python.layers.convolutional.Conv2D object at 0x0000029C74F98D88>>: AssertionError: Bad argument number for Name: 3, expecting 4\n",
      "WARNING:tensorflow:Entity <bound method Conv.call of <tensorflow.python.layers.convolutional.Conv2D object at 0x0000029C751D51C8>> could not be transformed and will be executed as-is. Please report this to the AutgoGraph team. When filing the bug, set the verbosity to 10 (on Linux, `export AUTOGRAPH_VERBOSITY=10`) and attach the full output. Cause: converting <bound method Conv.call of <tensorflow.python.layers.convolutional.Conv2D object at 0x0000029C751D51C8>>: AssertionError: Bad argument number for Name: 3, expecting 4\n",
      "WARNING: Entity <bound method Conv.call of <tensorflow.python.layers.convolutional.Conv2D object at 0x0000029C751D51C8>> could not be transformed and will be executed as-is. Please report this to the AutgoGraph team. When filing the bug, set the verbosity to 10 (on Linux, `export AUTOGRAPH_VERBOSITY=10`) and attach the full output. Cause: converting <bound method Conv.call of <tensorflow.python.layers.convolutional.Conv2D object at 0x0000029C751D51C8>>: AssertionError: Bad argument number for Name: 3, expecting 4\n",
      "WARNING:tensorflow:Entity <bound method Conv.call of <tensorflow.python.layers.convolutional.Conv2D object at 0x0000029C74F98D88>> could not be transformed and will be executed as-is. Please report this to the AutgoGraph team. When filing the bug, set the verbosity to 10 (on Linux, `export AUTOGRAPH_VERBOSITY=10`) and attach the full output. Cause: converting <bound method Conv.call of <tensorflow.python.layers.convolutional.Conv2D object at 0x0000029C74F98D88>>: AssertionError: Bad argument number for Name: 3, expecting 4\n",
      "WARNING: Entity <bound method Conv.call of <tensorflow.python.layers.convolutional.Conv2D object at 0x0000029C74F98D88>> could not be transformed and will be executed as-is. Please report this to the AutgoGraph team. When filing the bug, set the verbosity to 10 (on Linux, `export AUTOGRAPH_VERBOSITY=10`) and attach the full output. Cause: converting <bound method Conv.call of <tensorflow.python.layers.convolutional.Conv2D object at 0x0000029C74F98D88>>: AssertionError: Bad argument number for Name: 3, expecting 4\n",
      "WARNING:tensorflow:Entity <bound method Conv.call of <tensorflow.python.layers.convolutional.Conv2D object at 0x0000029C751D51C8>> could not be transformed and will be executed as-is. Please report this to the AutgoGraph team. When filing the bug, set the verbosity to 10 (on Linux, `export AUTOGRAPH_VERBOSITY=10`) and attach the full output. Cause: converting <bound method Conv.call of <tensorflow.python.layers.convolutional.Conv2D object at 0x0000029C751D51C8>>: AssertionError: Bad argument number for Name: 3, expecting 4\n",
      "WARNING: Entity <bound method Conv.call of <tensorflow.python.layers.convolutional.Conv2D object at 0x0000029C751D51C8>> could not be transformed and will be executed as-is. Please report this to the AutgoGraph team. When filing the bug, set the verbosity to 10 (on Linux, `export AUTOGRAPH_VERBOSITY=10`) and attach the full output. Cause: converting <bound method Conv.call of <tensorflow.python.layers.convolutional.Conv2D object at 0x0000029C751D51C8>>: AssertionError: Bad argument number for Name: 3, expecting 4\n",
      "WARNING:tensorflow:Entity <bound method Conv.call of <tensorflow.python.layers.convolutional.Conv2D object at 0x0000029C74F98D88>> could not be transformed and will be executed as-is. Please report this to the AutgoGraph team. When filing the bug, set the verbosity to 10 (on Linux, `export AUTOGRAPH_VERBOSITY=10`) and attach the full output. Cause: converting <bound method Conv.call of <tensorflow.python.layers.convolutional.Conv2D object at 0x0000029C74F98D88>>: AssertionError: Bad argument number for Name: 3, expecting 4\n",
      "WARNING: Entity <bound method Conv.call of <tensorflow.python.layers.convolutional.Conv2D object at 0x0000029C74F98D88>> could not be transformed and will be executed as-is. Please report this to the AutgoGraph team. When filing the bug, set the verbosity to 10 (on Linux, `export AUTOGRAPH_VERBOSITY=10`) and attach the full output. Cause: converting <bound method Conv.call of <tensorflow.python.layers.convolutional.Conv2D object at 0x0000029C74F98D88>>: AssertionError: Bad argument number for Name: 3, expecting 4\n",
      "WARNING:tensorflow:Entity <bound method Conv.call of <tensorflow.python.layers.convolutional.Conv2D object at 0x0000029C751D51C8>> could not be transformed and will be executed as-is. Please report this to the AutgoGraph team. When filing the bug, set the verbosity to 10 (on Linux, `export AUTOGRAPH_VERBOSITY=10`) and attach the full output. Cause: converting <bound method Conv.call of <tensorflow.python.layers.convolutional.Conv2D object at 0x0000029C751D51C8>>: AssertionError: Bad argument number for Name: 3, expecting 4\n",
      "WARNING: Entity <bound method Conv.call of <tensorflow.python.layers.convolutional.Conv2D object at 0x0000029C751D51C8>> could not be transformed and will be executed as-is. Please report this to the AutgoGraph team. When filing the bug, set the verbosity to 10 (on Linux, `export AUTOGRAPH_VERBOSITY=10`) and attach the full output. Cause: converting <bound method Conv.call of <tensorflow.python.layers.convolutional.Conv2D object at 0x0000029C751D51C8>>: AssertionError: Bad argument number for Name: 3, expecting 4\n",
      "WARNING:tensorflow:Entity <bound method Conv.call of <tensorflow.python.layers.convolutional.Conv2D object at 0x0000029C74F98D88>> could not be transformed and will be executed as-is. Please report this to the AutgoGraph team. When filing the bug, set the verbosity to 10 (on Linux, `export AUTOGRAPH_VERBOSITY=10`) and attach the full output. Cause: converting <bound method Conv.call of <tensorflow.python.layers.convolutional.Conv2D object at 0x0000029C74F98D88>>: AssertionError: Bad argument number for Name: 3, expecting 4\n"
     ]
    },
    {
     "name": "stdout",
     "output_type": "stream",
     "text": [
      "WARNING: Entity <bound method Conv.call of <tensorflow.python.layers.convolutional.Conv2D object at 0x0000029C74F98D88>> could not be transformed and will be executed as-is. Please report this to the AutgoGraph team. When filing the bug, set the verbosity to 10 (on Linux, `export AUTOGRAPH_VERBOSITY=10`) and attach the full output. Cause: converting <bound method Conv.call of <tensorflow.python.layers.convolutional.Conv2D object at 0x0000029C74F98D88>>: AssertionError: Bad argument number for Name: 3, expecting 4\n",
      "WARNING:tensorflow:Entity <bound method Conv.call of <tensorflow.python.layers.convolutional.Conv2D object at 0x0000029C751D51C8>> could not be transformed and will be executed as-is. Please report this to the AutgoGraph team. When filing the bug, set the verbosity to 10 (on Linux, `export AUTOGRAPH_VERBOSITY=10`) and attach the full output. Cause: converting <bound method Conv.call of <tensorflow.python.layers.convolutional.Conv2D object at 0x0000029C751D51C8>>: AssertionError: Bad argument number for Name: 3, expecting 4\n",
      "WARNING: Entity <bound method Conv.call of <tensorflow.python.layers.convolutional.Conv2D object at 0x0000029C751D51C8>> could not be transformed and will be executed as-is. Please report this to the AutgoGraph team. When filing the bug, set the verbosity to 10 (on Linux, `export AUTOGRAPH_VERBOSITY=10`) and attach the full output. Cause: converting <bound method Conv.call of <tensorflow.python.layers.convolutional.Conv2D object at 0x0000029C751D51C8>>: AssertionError: Bad argument number for Name: 3, expecting 4\n",
      "WARNING:tensorflow:Entity <bound method Conv.call of <tensorflow.python.layers.convolutional.Conv2D object at 0x0000029C74F98D88>> could not be transformed and will be executed as-is. Please report this to the AutgoGraph team. When filing the bug, set the verbosity to 10 (on Linux, `export AUTOGRAPH_VERBOSITY=10`) and attach the full output. Cause: converting <bound method Conv.call of <tensorflow.python.layers.convolutional.Conv2D object at 0x0000029C74F98D88>>: AssertionError: Bad argument number for Name: 3, expecting 4\n",
      "WARNING: Entity <bound method Conv.call of <tensorflow.python.layers.convolutional.Conv2D object at 0x0000029C74F98D88>> could not be transformed and will be executed as-is. Please report this to the AutgoGraph team. When filing the bug, set the verbosity to 10 (on Linux, `export AUTOGRAPH_VERBOSITY=10`) and attach the full output. Cause: converting <bound method Conv.call of <tensorflow.python.layers.convolutional.Conv2D object at 0x0000029C74F98D88>>: AssertionError: Bad argument number for Name: 3, expecting 4\n",
      "WARNING:tensorflow:Entity <bound method Conv.call of <tensorflow.python.layers.convolutional.Conv2D object at 0x0000029C751D51C8>> could not be transformed and will be executed as-is. Please report this to the AutgoGraph team. When filing the bug, set the verbosity to 10 (on Linux, `export AUTOGRAPH_VERBOSITY=10`) and attach the full output. Cause: converting <bound method Conv.call of <tensorflow.python.layers.convolutional.Conv2D object at 0x0000029C751D51C8>>: AssertionError: Bad argument number for Name: 3, expecting 4\n",
      "WARNING: Entity <bound method Conv.call of <tensorflow.python.layers.convolutional.Conv2D object at 0x0000029C751D51C8>> could not be transformed and will be executed as-is. Please report this to the AutgoGraph team. When filing the bug, set the verbosity to 10 (on Linux, `export AUTOGRAPH_VERBOSITY=10`) and attach the full output. Cause: converting <bound method Conv.call of <tensorflow.python.layers.convolutional.Conv2D object at 0x0000029C751D51C8>>: AssertionError: Bad argument number for Name: 3, expecting 4\n",
      "WARNING:tensorflow:Entity <bound method Conv.call of <tensorflow.python.layers.convolutional.Conv2D object at 0x0000029C74F98D88>> could not be transformed and will be executed as-is. Please report this to the AutgoGraph team. When filing the bug, set the verbosity to 10 (on Linux, `export AUTOGRAPH_VERBOSITY=10`) and attach the full output. Cause: converting <bound method Conv.call of <tensorflow.python.layers.convolutional.Conv2D object at 0x0000029C74F98D88>>: AssertionError: Bad argument number for Name: 3, expecting 4\n",
      "WARNING: Entity <bound method Conv.call of <tensorflow.python.layers.convolutional.Conv2D object at 0x0000029C74F98D88>> could not be transformed and will be executed as-is. Please report this to the AutgoGraph team. When filing the bug, set the verbosity to 10 (on Linux, `export AUTOGRAPH_VERBOSITY=10`) and attach the full output. Cause: converting <bound method Conv.call of <tensorflow.python.layers.convolutional.Conv2D object at 0x0000029C74F98D88>>: AssertionError: Bad argument number for Name: 3, expecting 4\n",
      "WARNING:tensorflow:Entity <bound method Conv.call of <tensorflow.python.layers.convolutional.Conv2D object at 0x0000029C751D51C8>> could not be transformed and will be executed as-is. Please report this to the AutgoGraph team. When filing the bug, set the verbosity to 10 (on Linux, `export AUTOGRAPH_VERBOSITY=10`) and attach the full output. Cause: converting <bound method Conv.call of <tensorflow.python.layers.convolutional.Conv2D object at 0x0000029C751D51C8>>: AssertionError: Bad argument number for Name: 3, expecting 4\n",
      "WARNING: Entity <bound method Conv.call of <tensorflow.python.layers.convolutional.Conv2D object at 0x0000029C751D51C8>> could not be transformed and will be executed as-is. Please report this to the AutgoGraph team. When filing the bug, set the verbosity to 10 (on Linux, `export AUTOGRAPH_VERBOSITY=10`) and attach the full output. Cause: converting <bound method Conv.call of <tensorflow.python.layers.convolutional.Conv2D object at 0x0000029C751D51C8>>: AssertionError: Bad argument number for Name: 3, expecting 4\n",
      "WARNING:tensorflow:Entity <bound method Conv.call of <tensorflow.python.layers.convolutional.Conv2D object at 0x0000029C74F98D88>> could not be transformed and will be executed as-is. Please report this to the AutgoGraph team. When filing the bug, set the verbosity to 10 (on Linux, `export AUTOGRAPH_VERBOSITY=10`) and attach the full output. Cause: converting <bound method Conv.call of <tensorflow.python.layers.convolutional.Conv2D object at 0x0000029C74F98D88>>: AssertionError: Bad argument number for Name: 3, expecting 4\n",
      "WARNING: Entity <bound method Conv.call of <tensorflow.python.layers.convolutional.Conv2D object at 0x0000029C74F98D88>> could not be transformed and will be executed as-is. Please report this to the AutgoGraph team. When filing the bug, set the verbosity to 10 (on Linux, `export AUTOGRAPH_VERBOSITY=10`) and attach the full output. Cause: converting <bound method Conv.call of <tensorflow.python.layers.convolutional.Conv2D object at 0x0000029C74F98D88>>: AssertionError: Bad argument number for Name: 3, expecting 4\n",
      "WARNING:tensorflow:Entity <bound method Conv.call of <tensorflow.python.layers.convolutional.Conv2D object at 0x0000029C751D51C8>> could not be transformed and will be executed as-is. Please report this to the AutgoGraph team. When filing the bug, set the verbosity to 10 (on Linux, `export AUTOGRAPH_VERBOSITY=10`) and attach the full output. Cause: converting <bound method Conv.call of <tensorflow.python.layers.convolutional.Conv2D object at 0x0000029C751D51C8>>: AssertionError: Bad argument number for Name: 3, expecting 4\n",
      "WARNING: Entity <bound method Conv.call of <tensorflow.python.layers.convolutional.Conv2D object at 0x0000029C751D51C8>> could not be transformed and will be executed as-is. Please report this to the AutgoGraph team. When filing the bug, set the verbosity to 10 (on Linux, `export AUTOGRAPH_VERBOSITY=10`) and attach the full output. Cause: converting <bound method Conv.call of <tensorflow.python.layers.convolutional.Conv2D object at 0x0000029C751D51C8>>: AssertionError: Bad argument number for Name: 3, expecting 4\n",
      "WARNING:tensorflow:Entity <bound method Conv.call of <tensorflow.python.layers.convolutional.Conv2D object at 0x0000029C74F98D88>> could not be transformed and will be executed as-is. Please report this to the AutgoGraph team. When filing the bug, set the verbosity to 10 (on Linux, `export AUTOGRAPH_VERBOSITY=10`) and attach the full output. Cause: converting <bound method Conv.call of <tensorflow.python.layers.convolutional.Conv2D object at 0x0000029C74F98D88>>: AssertionError: Bad argument number for Name: 3, expecting 4\n"
     ]
    },
    {
     "name": "stdout",
     "output_type": "stream",
     "text": [
      "WARNING: Entity <bound method Conv.call of <tensorflow.python.layers.convolutional.Conv2D object at 0x0000029C74F98D88>> could not be transformed and will be executed as-is. Please report this to the AutgoGraph team. When filing the bug, set the verbosity to 10 (on Linux, `export AUTOGRAPH_VERBOSITY=10`) and attach the full output. Cause: converting <bound method Conv.call of <tensorflow.python.layers.convolutional.Conv2D object at 0x0000029C74F98D88>>: AssertionError: Bad argument number for Name: 3, expecting 4\n",
      "WARNING:tensorflow:Entity <bound method Conv.call of <tensorflow.python.layers.convolutional.Conv2D object at 0x0000029C751D51C8>> could not be transformed and will be executed as-is. Please report this to the AutgoGraph team. When filing the bug, set the verbosity to 10 (on Linux, `export AUTOGRAPH_VERBOSITY=10`) and attach the full output. Cause: converting <bound method Conv.call of <tensorflow.python.layers.convolutional.Conv2D object at 0x0000029C751D51C8>>: AssertionError: Bad argument number for Name: 3, expecting 4\n",
      "WARNING: Entity <bound method Conv.call of <tensorflow.python.layers.convolutional.Conv2D object at 0x0000029C751D51C8>> could not be transformed and will be executed as-is. Please report this to the AutgoGraph team. When filing the bug, set the verbosity to 10 (on Linux, `export AUTOGRAPH_VERBOSITY=10`) and attach the full output. Cause: converting <bound method Conv.call of <tensorflow.python.layers.convolutional.Conv2D object at 0x0000029C751D51C8>>: AssertionError: Bad argument number for Name: 3, expecting 4\n",
      "WARNING:tensorflow:Entity <bound method Conv.call of <tensorflow.python.layers.convolutional.Conv2D object at 0x0000029C74F98D88>> could not be transformed and will be executed as-is. Please report this to the AutgoGraph team. When filing the bug, set the verbosity to 10 (on Linux, `export AUTOGRAPH_VERBOSITY=10`) and attach the full output. Cause: converting <bound method Conv.call of <tensorflow.python.layers.convolutional.Conv2D object at 0x0000029C74F98D88>>: AssertionError: Bad argument number for Name: 3, expecting 4\n",
      "WARNING: Entity <bound method Conv.call of <tensorflow.python.layers.convolutional.Conv2D object at 0x0000029C74F98D88>> could not be transformed and will be executed as-is. Please report this to the AutgoGraph team. When filing the bug, set the verbosity to 10 (on Linux, `export AUTOGRAPH_VERBOSITY=10`) and attach the full output. Cause: converting <bound method Conv.call of <tensorflow.python.layers.convolutional.Conv2D object at 0x0000029C74F98D88>>: AssertionError: Bad argument number for Name: 3, expecting 4\n",
      "WARNING:tensorflow:Entity <bound method Conv.call of <tensorflow.python.layers.convolutional.Conv2D object at 0x0000029C751D51C8>> could not be transformed and will be executed as-is. Please report this to the AutgoGraph team. When filing the bug, set the verbosity to 10 (on Linux, `export AUTOGRAPH_VERBOSITY=10`) and attach the full output. Cause: converting <bound method Conv.call of <tensorflow.python.layers.convolutional.Conv2D object at 0x0000029C751D51C8>>: AssertionError: Bad argument number for Name: 3, expecting 4\n",
      "WARNING: Entity <bound method Conv.call of <tensorflow.python.layers.convolutional.Conv2D object at 0x0000029C751D51C8>> could not be transformed and will be executed as-is. Please report this to the AutgoGraph team. When filing the bug, set the verbosity to 10 (on Linux, `export AUTOGRAPH_VERBOSITY=10`) and attach the full output. Cause: converting <bound method Conv.call of <tensorflow.python.layers.convolutional.Conv2D object at 0x0000029C751D51C8>>: AssertionError: Bad argument number for Name: 3, expecting 4\n",
      "WARNING:tensorflow:Entity <bound method Conv.call of <tensorflow.python.layers.convolutional.Conv2D object at 0x0000029C74F98D88>> could not be transformed and will be executed as-is. Please report this to the AutgoGraph team. When filing the bug, set the verbosity to 10 (on Linux, `export AUTOGRAPH_VERBOSITY=10`) and attach the full output. Cause: converting <bound method Conv.call of <tensorflow.python.layers.convolutional.Conv2D object at 0x0000029C74F98D88>>: AssertionError: Bad argument number for Name: 3, expecting 4\n",
      "WARNING: Entity <bound method Conv.call of <tensorflow.python.layers.convolutional.Conv2D object at 0x0000029C74F98D88>> could not be transformed and will be executed as-is. Please report this to the AutgoGraph team. When filing the bug, set the verbosity to 10 (on Linux, `export AUTOGRAPH_VERBOSITY=10`) and attach the full output. Cause: converting <bound method Conv.call of <tensorflow.python.layers.convolutional.Conv2D object at 0x0000029C74F98D88>>: AssertionError: Bad argument number for Name: 3, expecting 4\n",
      "WARNING:tensorflow:Entity <bound method Conv.call of <tensorflow.python.layers.convolutional.Conv2D object at 0x0000029C751D51C8>> could not be transformed and will be executed as-is. Please report this to the AutgoGraph team. When filing the bug, set the verbosity to 10 (on Linux, `export AUTOGRAPH_VERBOSITY=10`) and attach the full output. Cause: converting <bound method Conv.call of <tensorflow.python.layers.convolutional.Conv2D object at 0x0000029C751D51C8>>: AssertionError: Bad argument number for Name: 3, expecting 4\n",
      "WARNING: Entity <bound method Conv.call of <tensorflow.python.layers.convolutional.Conv2D object at 0x0000029C751D51C8>> could not be transformed and will be executed as-is. Please report this to the AutgoGraph team. When filing the bug, set the verbosity to 10 (on Linux, `export AUTOGRAPH_VERBOSITY=10`) and attach the full output. Cause: converting <bound method Conv.call of <tensorflow.python.layers.convolutional.Conv2D object at 0x0000029C751D51C8>>: AssertionError: Bad argument number for Name: 3, expecting 4\n",
      "WARNING:tensorflow:Entity <bound method Conv.call of <tensorflow.python.layers.convolutional.Conv2D object at 0x0000029C756A16C8>> could not be transformed and will be executed as-is. Please report this to the AutgoGraph team. When filing the bug, set the verbosity to 10 (on Linux, `export AUTOGRAPH_VERBOSITY=10`) and attach the full output. Cause: converting <bound method Conv.call of <tensorflow.python.layers.convolutional.Conv2D object at 0x0000029C756A16C8>>: AssertionError: Bad argument number for Name: 3, expecting 4\n",
      "WARNING: Entity <bound method Conv.call of <tensorflow.python.layers.convolutional.Conv2D object at 0x0000029C756A16C8>> could not be transformed and will be executed as-is. Please report this to the AutgoGraph team. When filing the bug, set the verbosity to 10 (on Linux, `export AUTOGRAPH_VERBOSITY=10`) and attach the full output. Cause: converting <bound method Conv.call of <tensorflow.python.layers.convolutional.Conv2D object at 0x0000029C756A16C8>>: AssertionError: Bad argument number for Name: 3, expecting 4\n",
      "WARNING:tensorflow:Entity <bound method Conv.call of <tensorflow.python.layers.convolutional.Conv2D object at 0x0000029C75834BC8>> could not be transformed and will be executed as-is. Please report this to the AutgoGraph team. When filing the bug, set the verbosity to 10 (on Linux, `export AUTOGRAPH_VERBOSITY=10`) and attach the full output. Cause: converting <bound method Conv.call of <tensorflow.python.layers.convolutional.Conv2D object at 0x0000029C75834BC8>>: AssertionError: Bad argument number for Name: 3, expecting 4\n",
      "WARNING: Entity <bound method Conv.call of <tensorflow.python.layers.convolutional.Conv2D object at 0x0000029C75834BC8>> could not be transformed and will be executed as-is. Please report this to the AutgoGraph team. When filing the bug, set the verbosity to 10 (on Linux, `export AUTOGRAPH_VERBOSITY=10`) and attach the full output. Cause: converting <bound method Conv.call of <tensorflow.python.layers.convolutional.Conv2D object at 0x0000029C75834BC8>>: AssertionError: Bad argument number for Name: 3, expecting 4\n",
      "WARNING:tensorflow:Entity <bound method Conv.call of <tensorflow.python.layers.convolutional.Conv2D object at 0x0000029C756D8988>> could not be transformed and will be executed as-is. Please report this to the AutgoGraph team. When filing the bug, set the verbosity to 10 (on Linux, `export AUTOGRAPH_VERBOSITY=10`) and attach the full output. Cause: converting <bound method Conv.call of <tensorflow.python.layers.convolutional.Conv2D object at 0x0000029C756D8988>>: AssertionError: Bad argument number for Name: 3, expecting 4\n"
     ]
    },
    {
     "name": "stdout",
     "output_type": "stream",
     "text": [
      "WARNING: Entity <bound method Conv.call of <tensorflow.python.layers.convolutional.Conv2D object at 0x0000029C756D8988>> could not be transformed and will be executed as-is. Please report this to the AutgoGraph team. When filing the bug, set the verbosity to 10 (on Linux, `export AUTOGRAPH_VERBOSITY=10`) and attach the full output. Cause: converting <bound method Conv.call of <tensorflow.python.layers.convolutional.Conv2D object at 0x0000029C756D8988>>: AssertionError: Bad argument number for Name: 3, expecting 4\n",
      "WARNING:tensorflow:Entity <bound method Conv.call of <tensorflow.python.layers.convolutional.Conv2D object at 0x0000029C75791FC8>> could not be transformed and will be executed as-is. Please report this to the AutgoGraph team. When filing the bug, set the verbosity to 10 (on Linux, `export AUTOGRAPH_VERBOSITY=10`) and attach the full output. Cause: converting <bound method Conv.call of <tensorflow.python.layers.convolutional.Conv2D object at 0x0000029C75791FC8>>: AssertionError: Bad argument number for Name: 3, expecting 4\n",
      "WARNING: Entity <bound method Conv.call of <tensorflow.python.layers.convolutional.Conv2D object at 0x0000029C75791FC8>> could not be transformed and will be executed as-is. Please report this to the AutgoGraph team. When filing the bug, set the verbosity to 10 (on Linux, `export AUTOGRAPH_VERBOSITY=10`) and attach the full output. Cause: converting <bound method Conv.call of <tensorflow.python.layers.convolutional.Conv2D object at 0x0000029C75791FC8>>: AssertionError: Bad argument number for Name: 3, expecting 4\n",
      "WARNING:tensorflow:Entity <bound method Conv.call of <tensorflow.python.layers.convolutional.Conv2D object at 0x0000029C756D8988>> could not be transformed and will be executed as-is. Please report this to the AutgoGraph team. When filing the bug, set the verbosity to 10 (on Linux, `export AUTOGRAPH_VERBOSITY=10`) and attach the full output. Cause: converting <bound method Conv.call of <tensorflow.python.layers.convolutional.Conv2D object at 0x0000029C756D8988>>: AssertionError: Bad argument number for Name: 3, expecting 4\n",
      "WARNING: Entity <bound method Conv.call of <tensorflow.python.layers.convolutional.Conv2D object at 0x0000029C756D8988>> could not be transformed and will be executed as-is. Please report this to the AutgoGraph team. When filing the bug, set the verbosity to 10 (on Linux, `export AUTOGRAPH_VERBOSITY=10`) and attach the full output. Cause: converting <bound method Conv.call of <tensorflow.python.layers.convolutional.Conv2D object at 0x0000029C756D8988>>: AssertionError: Bad argument number for Name: 3, expecting 4\n",
      "WARNING:tensorflow:Entity <bound method Conv.call of <tensorflow.python.layers.convolutional.Conv2D object at 0x0000029C75791FC8>> could not be transformed and will be executed as-is. Please report this to the AutgoGraph team. When filing the bug, set the verbosity to 10 (on Linux, `export AUTOGRAPH_VERBOSITY=10`) and attach the full output. Cause: converting <bound method Conv.call of <tensorflow.python.layers.convolutional.Conv2D object at 0x0000029C75791FC8>>: AssertionError: Bad argument number for Name: 3, expecting 4\n",
      "WARNING: Entity <bound method Conv.call of <tensorflow.python.layers.convolutional.Conv2D object at 0x0000029C75791FC8>> could not be transformed and will be executed as-is. Please report this to the AutgoGraph team. When filing the bug, set the verbosity to 10 (on Linux, `export AUTOGRAPH_VERBOSITY=10`) and attach the full output. Cause: converting <bound method Conv.call of <tensorflow.python.layers.convolutional.Conv2D object at 0x0000029C75791FC8>>: AssertionError: Bad argument number for Name: 3, expecting 4\n",
      "WARNING:tensorflow:Entity <bound method Conv.call of <tensorflow.python.layers.convolutional.Conv2D object at 0x0000029C75791FC8>> could not be transformed and will be executed as-is. Please report this to the AutgoGraph team. When filing the bug, set the verbosity to 10 (on Linux, `export AUTOGRAPH_VERBOSITY=10`) and attach the full output. Cause: converting <bound method Conv.call of <tensorflow.python.layers.convolutional.Conv2D object at 0x0000029C75791FC8>>: AssertionError: Bad argument number for Name: 3, expecting 4\n",
      "WARNING: Entity <bound method Conv.call of <tensorflow.python.layers.convolutional.Conv2D object at 0x0000029C75791FC8>> could not be transformed and will be executed as-is. Please report this to the AutgoGraph team. When filing the bug, set the verbosity to 10 (on Linux, `export AUTOGRAPH_VERBOSITY=10`) and attach the full output. Cause: converting <bound method Conv.call of <tensorflow.python.layers.convolutional.Conv2D object at 0x0000029C75791FC8>>: AssertionError: Bad argument number for Name: 3, expecting 4\n",
      "WARNING:tensorflow:Entity <bound method Conv.call of <tensorflow.python.layers.convolutional.Conv2D object at 0x0000029C758937C8>> could not be transformed and will be executed as-is. Please report this to the AutgoGraph team. When filing the bug, set the verbosity to 10 (on Linux, `export AUTOGRAPH_VERBOSITY=10`) and attach the full output. Cause: converting <bound method Conv.call of <tensorflow.python.layers.convolutional.Conv2D object at 0x0000029C758937C8>>: AssertionError: Bad argument number for Name: 3, expecting 4\n",
      "WARNING: Entity <bound method Conv.call of <tensorflow.python.layers.convolutional.Conv2D object at 0x0000029C758937C8>> could not be transformed and will be executed as-is. Please report this to the AutgoGraph team. When filing the bug, set the verbosity to 10 (on Linux, `export AUTOGRAPH_VERBOSITY=10`) and attach the full output. Cause: converting <bound method Conv.call of <tensorflow.python.layers.convolutional.Conv2D object at 0x0000029C758937C8>>: AssertionError: Bad argument number for Name: 3, expecting 4\n",
      "WARNING:tensorflow:Entity <bound method Conv.call of <tensorflow.python.layers.convolutional.Conv2D object at 0x0000029C75791FC8>> could not be transformed and will be executed as-is. Please report this to the AutgoGraph team. When filing the bug, set the verbosity to 10 (on Linux, `export AUTOGRAPH_VERBOSITY=10`) and attach the full output. Cause: converting <bound method Conv.call of <tensorflow.python.layers.convolutional.Conv2D object at 0x0000029C75791FC8>>: AssertionError: Bad argument number for Name: 3, expecting 4\n",
      "WARNING: Entity <bound method Conv.call of <tensorflow.python.layers.convolutional.Conv2D object at 0x0000029C75791FC8>> could not be transformed and will be executed as-is. Please report this to the AutgoGraph team. When filing the bug, set the verbosity to 10 (on Linux, `export AUTOGRAPH_VERBOSITY=10`) and attach the full output. Cause: converting <bound method Conv.call of <tensorflow.python.layers.convolutional.Conv2D object at 0x0000029C75791FC8>>: AssertionError: Bad argument number for Name: 3, expecting 4\n",
      "WARNING:tensorflow:Entity <bound method Conv.call of <tensorflow.python.layers.convolutional.Conv2D object at 0x0000029C758937C8>> could not be transformed and will be executed as-is. Please report this to the AutgoGraph team. When filing the bug, set the verbosity to 10 (on Linux, `export AUTOGRAPH_VERBOSITY=10`) and attach the full output. Cause: converting <bound method Conv.call of <tensorflow.python.layers.convolutional.Conv2D object at 0x0000029C758937C8>>: AssertionError: Bad argument number for Name: 3, expecting 4\n",
      "WARNING: Entity <bound method Conv.call of <tensorflow.python.layers.convolutional.Conv2D object at 0x0000029C758937C8>> could not be transformed and will be executed as-is. Please report this to the AutgoGraph team. When filing the bug, set the verbosity to 10 (on Linux, `export AUTOGRAPH_VERBOSITY=10`) and attach the full output. Cause: converting <bound method Conv.call of <tensorflow.python.layers.convolutional.Conv2D object at 0x0000029C758937C8>>: AssertionError: Bad argument number for Name: 3, expecting 4\n",
      "WARNING:tensorflow:Entity <bound method Conv.call of <tensorflow.python.layers.convolutional.Conv2D object at 0x0000029C756D8988>> could not be transformed and will be executed as-is. Please report this to the AutgoGraph team. When filing the bug, set the verbosity to 10 (on Linux, `export AUTOGRAPH_VERBOSITY=10`) and attach the full output. Cause: converting <bound method Conv.call of <tensorflow.python.layers.convolutional.Conv2D object at 0x0000029C756D8988>>: AssertionError: Bad argument number for Name: 3, expecting 4\n"
     ]
    },
    {
     "name": "stdout",
     "output_type": "stream",
     "text": [
      "WARNING: Entity <bound method Conv.call of <tensorflow.python.layers.convolutional.Conv2D object at 0x0000029C756D8988>> could not be transformed and will be executed as-is. Please report this to the AutgoGraph team. When filing the bug, set the verbosity to 10 (on Linux, `export AUTOGRAPH_VERBOSITY=10`) and attach the full output. Cause: converting <bound method Conv.call of <tensorflow.python.layers.convolutional.Conv2D object at 0x0000029C756D8988>>: AssertionError: Bad argument number for Name: 3, expecting 4\n",
      "WARNING:tensorflow:Entity <bound method Conv.call of <tensorflow.python.layers.convolutional.Conv2D object at 0x0000029C75791FC8>> could not be transformed and will be executed as-is. Please report this to the AutgoGraph team. When filing the bug, set the verbosity to 10 (on Linux, `export AUTOGRAPH_VERBOSITY=10`) and attach the full output. Cause: converting <bound method Conv.call of <tensorflow.python.layers.convolutional.Conv2D object at 0x0000029C75791FC8>>: AssertionError: Bad argument number for Name: 3, expecting 4\n",
      "WARNING: Entity <bound method Conv.call of <tensorflow.python.layers.convolutional.Conv2D object at 0x0000029C75791FC8>> could not be transformed and will be executed as-is. Please report this to the AutgoGraph team. When filing the bug, set the verbosity to 10 (on Linux, `export AUTOGRAPH_VERBOSITY=10`) and attach the full output. Cause: converting <bound method Conv.call of <tensorflow.python.layers.convolutional.Conv2D object at 0x0000029C75791FC8>>: AssertionError: Bad argument number for Name: 3, expecting 4\n",
      "WARNING:tensorflow:Entity <bound method Conv.call of <tensorflow.python.layers.convolutional.Conv2D object at 0x0000029C756D8988>> could not be transformed and will be executed as-is. Please report this to the AutgoGraph team. When filing the bug, set the verbosity to 10 (on Linux, `export AUTOGRAPH_VERBOSITY=10`) and attach the full output. Cause: converting <bound method Conv.call of <tensorflow.python.layers.convolutional.Conv2D object at 0x0000029C756D8988>>: AssertionError: Bad argument number for Name: 3, expecting 4\n",
      "WARNING: Entity <bound method Conv.call of <tensorflow.python.layers.convolutional.Conv2D object at 0x0000029C756D8988>> could not be transformed and will be executed as-is. Please report this to the AutgoGraph team. When filing the bug, set the verbosity to 10 (on Linux, `export AUTOGRAPH_VERBOSITY=10`) and attach the full output. Cause: converting <bound method Conv.call of <tensorflow.python.layers.convolutional.Conv2D object at 0x0000029C756D8988>>: AssertionError: Bad argument number for Name: 3, expecting 4\n",
      "WARNING:tensorflow:Entity <bound method Conv.call of <tensorflow.python.layers.convolutional.Conv2D object at 0x0000029C75791FC8>> could not be transformed and will be executed as-is. Please report this to the AutgoGraph team. When filing the bug, set the verbosity to 10 (on Linux, `export AUTOGRAPH_VERBOSITY=10`) and attach the full output. Cause: converting <bound method Conv.call of <tensorflow.python.layers.convolutional.Conv2D object at 0x0000029C75791FC8>>: AssertionError: Bad argument number for Name: 3, expecting 4\n",
      "WARNING: Entity <bound method Conv.call of <tensorflow.python.layers.convolutional.Conv2D object at 0x0000029C75791FC8>> could not be transformed and will be executed as-is. Please report this to the AutgoGraph team. When filing the bug, set the verbosity to 10 (on Linux, `export AUTOGRAPH_VERBOSITY=10`) and attach the full output. Cause: converting <bound method Conv.call of <tensorflow.python.layers.convolutional.Conv2D object at 0x0000029C75791FC8>>: AssertionError: Bad argument number for Name: 3, expecting 4\n",
      "WARNING:tensorflow:Entity <bound method Conv.call of <tensorflow.python.layers.convolutional.Conv2D object at 0x0000029C756D8988>> could not be transformed and will be executed as-is. Please report this to the AutgoGraph team. When filing the bug, set the verbosity to 10 (on Linux, `export AUTOGRAPH_VERBOSITY=10`) and attach the full output. Cause: converting <bound method Conv.call of <tensorflow.python.layers.convolutional.Conv2D object at 0x0000029C756D8988>>: AssertionError: Bad argument number for Name: 3, expecting 4\n",
      "WARNING: Entity <bound method Conv.call of <tensorflow.python.layers.convolutional.Conv2D object at 0x0000029C756D8988>> could not be transformed and will be executed as-is. Please report this to the AutgoGraph team. When filing the bug, set the verbosity to 10 (on Linux, `export AUTOGRAPH_VERBOSITY=10`) and attach the full output. Cause: converting <bound method Conv.call of <tensorflow.python.layers.convolutional.Conv2D object at 0x0000029C756D8988>>: AssertionError: Bad argument number for Name: 3, expecting 4\n",
      "WARNING:tensorflow:Entity <bound method Conv.call of <tensorflow.python.layers.convolutional.Conv2D object at 0x0000029C75791FC8>> could not be transformed and will be executed as-is. Please report this to the AutgoGraph team. When filing the bug, set the verbosity to 10 (on Linux, `export AUTOGRAPH_VERBOSITY=10`) and attach the full output. Cause: converting <bound method Conv.call of <tensorflow.python.layers.convolutional.Conv2D object at 0x0000029C75791FC8>>: AssertionError: Bad argument number for Name: 3, expecting 4\n",
      "WARNING: Entity <bound method Conv.call of <tensorflow.python.layers.convolutional.Conv2D object at 0x0000029C75791FC8>> could not be transformed and will be executed as-is. Please report this to the AutgoGraph team. When filing the bug, set the verbosity to 10 (on Linux, `export AUTOGRAPH_VERBOSITY=10`) and attach the full output. Cause: converting <bound method Conv.call of <tensorflow.python.layers.convolutional.Conv2D object at 0x0000029C75791FC8>>: AssertionError: Bad argument number for Name: 3, expecting 4\n",
      "WARNING:tensorflow:Entity <bound method Conv.call of <tensorflow.python.layers.convolutional.Conv2D object at 0x0000029C756D8988>> could not be transformed and will be executed as-is. Please report this to the AutgoGraph team. When filing the bug, set the verbosity to 10 (on Linux, `export AUTOGRAPH_VERBOSITY=10`) and attach the full output. Cause: converting <bound method Conv.call of <tensorflow.python.layers.convolutional.Conv2D object at 0x0000029C756D8988>>: AssertionError: Bad argument number for Name: 3, expecting 4\n",
      "WARNING: Entity <bound method Conv.call of <tensorflow.python.layers.convolutional.Conv2D object at 0x0000029C756D8988>> could not be transformed and will be executed as-is. Please report this to the AutgoGraph team. When filing the bug, set the verbosity to 10 (on Linux, `export AUTOGRAPH_VERBOSITY=10`) and attach the full output. Cause: converting <bound method Conv.call of <tensorflow.python.layers.convolutional.Conv2D object at 0x0000029C756D8988>>: AssertionError: Bad argument number for Name: 3, expecting 4\n",
      "WARNING:tensorflow:Entity <bound method Conv.call of <tensorflow.python.layers.convolutional.Conv2D object at 0x0000029C75791FC8>> could not be transformed and will be executed as-is. Please report this to the AutgoGraph team. When filing the bug, set the verbosity to 10 (on Linux, `export AUTOGRAPH_VERBOSITY=10`) and attach the full output. Cause: converting <bound method Conv.call of <tensorflow.python.layers.convolutional.Conv2D object at 0x0000029C75791FC8>>: AssertionError: Bad argument number for Name: 3, expecting 4\n",
      "WARNING: Entity <bound method Conv.call of <tensorflow.python.layers.convolutional.Conv2D object at 0x0000029C75791FC8>> could not be transformed and will be executed as-is. Please report this to the AutgoGraph team. When filing the bug, set the verbosity to 10 (on Linux, `export AUTOGRAPH_VERBOSITY=10`) and attach the full output. Cause: converting <bound method Conv.call of <tensorflow.python.layers.convolutional.Conv2D object at 0x0000029C75791FC8>>: AssertionError: Bad argument number for Name: 3, expecting 4\n",
      "WARNING:tensorflow:Entity <bound method Conv.call of <tensorflow.python.layers.convolutional.Conv2D object at 0x0000029C756D8988>> could not be transformed and will be executed as-is. Please report this to the AutgoGraph team. When filing the bug, set the verbosity to 10 (on Linux, `export AUTOGRAPH_VERBOSITY=10`) and attach the full output. Cause: converting <bound method Conv.call of <tensorflow.python.layers.convolutional.Conv2D object at 0x0000029C756D8988>>: AssertionError: Bad argument number for Name: 3, expecting 4\n"
     ]
    },
    {
     "name": "stdout",
     "output_type": "stream",
     "text": [
      "WARNING: Entity <bound method Conv.call of <tensorflow.python.layers.convolutional.Conv2D object at 0x0000029C756D8988>> could not be transformed and will be executed as-is. Please report this to the AutgoGraph team. When filing the bug, set the verbosity to 10 (on Linux, `export AUTOGRAPH_VERBOSITY=10`) and attach the full output. Cause: converting <bound method Conv.call of <tensorflow.python.layers.convolutional.Conv2D object at 0x0000029C756D8988>>: AssertionError: Bad argument number for Name: 3, expecting 4\n",
      "WARNING:tensorflow:Entity <bound method Conv.call of <tensorflow.python.layers.convolutional.Conv2D object at 0x0000029C75791FC8>> could not be transformed and will be executed as-is. Please report this to the AutgoGraph team. When filing the bug, set the verbosity to 10 (on Linux, `export AUTOGRAPH_VERBOSITY=10`) and attach the full output. Cause: converting <bound method Conv.call of <tensorflow.python.layers.convolutional.Conv2D object at 0x0000029C75791FC8>>: AssertionError: Bad argument number for Name: 3, expecting 4\n",
      "WARNING: Entity <bound method Conv.call of <tensorflow.python.layers.convolutional.Conv2D object at 0x0000029C75791FC8>> could not be transformed and will be executed as-is. Please report this to the AutgoGraph team. When filing the bug, set the verbosity to 10 (on Linux, `export AUTOGRAPH_VERBOSITY=10`) and attach the full output. Cause: converting <bound method Conv.call of <tensorflow.python.layers.convolutional.Conv2D object at 0x0000029C75791FC8>>: AssertionError: Bad argument number for Name: 3, expecting 4\n",
      "WARNING:tensorflow:Entity <bound method Conv.call of <tensorflow.python.layers.convolutional.Conv2D object at 0x0000029C756D8988>> could not be transformed and will be executed as-is. Please report this to the AutgoGraph team. When filing the bug, set the verbosity to 10 (on Linux, `export AUTOGRAPH_VERBOSITY=10`) and attach the full output. Cause: converting <bound method Conv.call of <tensorflow.python.layers.convolutional.Conv2D object at 0x0000029C756D8988>>: AssertionError: Bad argument number for Name: 3, expecting 4\n",
      "WARNING: Entity <bound method Conv.call of <tensorflow.python.layers.convolutional.Conv2D object at 0x0000029C756D8988>> could not be transformed and will be executed as-is. Please report this to the AutgoGraph team. When filing the bug, set the verbosity to 10 (on Linux, `export AUTOGRAPH_VERBOSITY=10`) and attach the full output. Cause: converting <bound method Conv.call of <tensorflow.python.layers.convolutional.Conv2D object at 0x0000029C756D8988>>: AssertionError: Bad argument number for Name: 3, expecting 4\n",
      "WARNING:tensorflow:Entity <bound method Conv.call of <tensorflow.python.layers.convolutional.Conv2D object at 0x0000029C75791FC8>> could not be transformed and will be executed as-is. Please report this to the AutgoGraph team. When filing the bug, set the verbosity to 10 (on Linux, `export AUTOGRAPH_VERBOSITY=10`) and attach the full output. Cause: converting <bound method Conv.call of <tensorflow.python.layers.convolutional.Conv2D object at 0x0000029C75791FC8>>: AssertionError: Bad argument number for Name: 3, expecting 4\n",
      "WARNING: Entity <bound method Conv.call of <tensorflow.python.layers.convolutional.Conv2D object at 0x0000029C75791FC8>> could not be transformed and will be executed as-is. Please report this to the AutgoGraph team. When filing the bug, set the verbosity to 10 (on Linux, `export AUTOGRAPH_VERBOSITY=10`) and attach the full output. Cause: converting <bound method Conv.call of <tensorflow.python.layers.convolutional.Conv2D object at 0x0000029C75791FC8>>: AssertionError: Bad argument number for Name: 3, expecting 4\n",
      "WARNING:tensorflow:Entity <bound method Conv.call of <tensorflow.python.layers.convolutional.Conv2D object at 0x0000029C756D8988>> could not be transformed and will be executed as-is. Please report this to the AutgoGraph team. When filing the bug, set the verbosity to 10 (on Linux, `export AUTOGRAPH_VERBOSITY=10`) and attach the full output. Cause: converting <bound method Conv.call of <tensorflow.python.layers.convolutional.Conv2D object at 0x0000029C756D8988>>: AssertionError: Bad argument number for Name: 3, expecting 4\n",
      "WARNING: Entity <bound method Conv.call of <tensorflow.python.layers.convolutional.Conv2D object at 0x0000029C756D8988>> could not be transformed and will be executed as-is. Please report this to the AutgoGraph team. When filing the bug, set the verbosity to 10 (on Linux, `export AUTOGRAPH_VERBOSITY=10`) and attach the full output. Cause: converting <bound method Conv.call of <tensorflow.python.layers.convolutional.Conv2D object at 0x0000029C756D8988>>: AssertionError: Bad argument number for Name: 3, expecting 4\n",
      "WARNING:tensorflow:Entity <bound method Conv.call of <tensorflow.python.layers.convolutional.Conv2D object at 0x0000029C75791FC8>> could not be transformed and will be executed as-is. Please report this to the AutgoGraph team. When filing the bug, set the verbosity to 10 (on Linux, `export AUTOGRAPH_VERBOSITY=10`) and attach the full output. Cause: converting <bound method Conv.call of <tensorflow.python.layers.convolutional.Conv2D object at 0x0000029C75791FC8>>: AssertionError: Bad argument number for Name: 3, expecting 4\n",
      "WARNING: Entity <bound method Conv.call of <tensorflow.python.layers.convolutional.Conv2D object at 0x0000029C75791FC8>> could not be transformed and will be executed as-is. Please report this to the AutgoGraph team. When filing the bug, set the verbosity to 10 (on Linux, `export AUTOGRAPH_VERBOSITY=10`) and attach the full output. Cause: converting <bound method Conv.call of <tensorflow.python.layers.convolutional.Conv2D object at 0x0000029C75791FC8>>: AssertionError: Bad argument number for Name: 3, expecting 4\n",
      "WARNING:tensorflow:Entity <bound method Conv.call of <tensorflow.python.layers.convolutional.Conv2D object at 0x0000029C756D8988>> could not be transformed and will be executed as-is. Please report this to the AutgoGraph team. When filing the bug, set the verbosity to 10 (on Linux, `export AUTOGRAPH_VERBOSITY=10`) and attach the full output. Cause: converting <bound method Conv.call of <tensorflow.python.layers.convolutional.Conv2D object at 0x0000029C756D8988>>: AssertionError: Bad argument number for Name: 3, expecting 4\n",
      "WARNING: Entity <bound method Conv.call of <tensorflow.python.layers.convolutional.Conv2D object at 0x0000029C756D8988>> could not be transformed and will be executed as-is. Please report this to the AutgoGraph team. When filing the bug, set the verbosity to 10 (on Linux, `export AUTOGRAPH_VERBOSITY=10`) and attach the full output. Cause: converting <bound method Conv.call of <tensorflow.python.layers.convolutional.Conv2D object at 0x0000029C756D8988>>: AssertionError: Bad argument number for Name: 3, expecting 4\n",
      "WARNING:tensorflow:Entity <bound method Conv.call of <tensorflow.python.layers.convolutional.Conv2D object at 0x0000029C75791FC8>> could not be transformed and will be executed as-is. Please report this to the AutgoGraph team. When filing the bug, set the verbosity to 10 (on Linux, `export AUTOGRAPH_VERBOSITY=10`) and attach the full output. Cause: converting <bound method Conv.call of <tensorflow.python.layers.convolutional.Conv2D object at 0x0000029C75791FC8>>: AssertionError: Bad argument number for Name: 3, expecting 4\n",
      "WARNING: Entity <bound method Conv.call of <tensorflow.python.layers.convolutional.Conv2D object at 0x0000029C75791FC8>> could not be transformed and will be executed as-is. Please report this to the AutgoGraph team. When filing the bug, set the verbosity to 10 (on Linux, `export AUTOGRAPH_VERBOSITY=10`) and attach the full output. Cause: converting <bound method Conv.call of <tensorflow.python.layers.convolutional.Conv2D object at 0x0000029C75791FC8>>: AssertionError: Bad argument number for Name: 3, expecting 4\n",
      "WARNING:tensorflow:Entity <bound method Conv.call of <tensorflow.python.layers.convolutional.Conv2D object at 0x0000029C756D8988>> could not be transformed and will be executed as-is. Please report this to the AutgoGraph team. When filing the bug, set the verbosity to 10 (on Linux, `export AUTOGRAPH_VERBOSITY=10`) and attach the full output. Cause: converting <bound method Conv.call of <tensorflow.python.layers.convolutional.Conv2D object at 0x0000029C756D8988>>: AssertionError: Bad argument number for Name: 3, expecting 4\n"
     ]
    },
    {
     "name": "stdout",
     "output_type": "stream",
     "text": [
      "WARNING: Entity <bound method Conv.call of <tensorflow.python.layers.convolutional.Conv2D object at 0x0000029C756D8988>> could not be transformed and will be executed as-is. Please report this to the AutgoGraph team. When filing the bug, set the verbosity to 10 (on Linux, `export AUTOGRAPH_VERBOSITY=10`) and attach the full output. Cause: converting <bound method Conv.call of <tensorflow.python.layers.convolutional.Conv2D object at 0x0000029C756D8988>>: AssertionError: Bad argument number for Name: 3, expecting 4\n",
      "WARNING:tensorflow:Entity <bound method Conv.call of <tensorflow.python.layers.convolutional.Conv2D object at 0x0000029C75791FC8>> could not be transformed and will be executed as-is. Please report this to the AutgoGraph team. When filing the bug, set the verbosity to 10 (on Linux, `export AUTOGRAPH_VERBOSITY=10`) and attach the full output. Cause: converting <bound method Conv.call of <tensorflow.python.layers.convolutional.Conv2D object at 0x0000029C75791FC8>>: AssertionError: Bad argument number for Name: 3, expecting 4\n",
      "WARNING: Entity <bound method Conv.call of <tensorflow.python.layers.convolutional.Conv2D object at 0x0000029C75791FC8>> could not be transformed and will be executed as-is. Please report this to the AutgoGraph team. When filing the bug, set the verbosity to 10 (on Linux, `export AUTOGRAPH_VERBOSITY=10`) and attach the full output. Cause: converting <bound method Conv.call of <tensorflow.python.layers.convolutional.Conv2D object at 0x0000029C75791FC8>>: AssertionError: Bad argument number for Name: 3, expecting 4\n",
      "WARNING:tensorflow:Entity <bound method Conv.call of <tensorflow.python.layers.convolutional.Conv2D object at 0x0000029C756D8988>> could not be transformed and will be executed as-is. Please report this to the AutgoGraph team. When filing the bug, set the verbosity to 10 (on Linux, `export AUTOGRAPH_VERBOSITY=10`) and attach the full output. Cause: converting <bound method Conv.call of <tensorflow.python.layers.convolutional.Conv2D object at 0x0000029C756D8988>>: AssertionError: Bad argument number for Name: 3, expecting 4\n",
      "WARNING: Entity <bound method Conv.call of <tensorflow.python.layers.convolutional.Conv2D object at 0x0000029C756D8988>> could not be transformed and will be executed as-is. Please report this to the AutgoGraph team. When filing the bug, set the verbosity to 10 (on Linux, `export AUTOGRAPH_VERBOSITY=10`) and attach the full output. Cause: converting <bound method Conv.call of <tensorflow.python.layers.convolutional.Conv2D object at 0x0000029C756D8988>>: AssertionError: Bad argument number for Name: 3, expecting 4\n",
      "WARNING:tensorflow:Entity <bound method Conv.call of <tensorflow.python.layers.convolutional.Conv2D object at 0x0000029C75791FC8>> could not be transformed and will be executed as-is. Please report this to the AutgoGraph team. When filing the bug, set the verbosity to 10 (on Linux, `export AUTOGRAPH_VERBOSITY=10`) and attach the full output. Cause: converting <bound method Conv.call of <tensorflow.python.layers.convolutional.Conv2D object at 0x0000029C75791FC8>>: AssertionError: Bad argument number for Name: 3, expecting 4\n",
      "WARNING: Entity <bound method Conv.call of <tensorflow.python.layers.convolutional.Conv2D object at 0x0000029C75791FC8>> could not be transformed and will be executed as-is. Please report this to the AutgoGraph team. When filing the bug, set the verbosity to 10 (on Linux, `export AUTOGRAPH_VERBOSITY=10`) and attach the full output. Cause: converting <bound method Conv.call of <tensorflow.python.layers.convolutional.Conv2D object at 0x0000029C75791FC8>>: AssertionError: Bad argument number for Name: 3, expecting 4\n",
      "WARNING:tensorflow:Entity <bound method Conv.call of <tensorflow.python.layers.convolutional.Conv2D object at 0x0000029C756D8988>> could not be transformed and will be executed as-is. Please report this to the AutgoGraph team. When filing the bug, set the verbosity to 10 (on Linux, `export AUTOGRAPH_VERBOSITY=10`) and attach the full output. Cause: converting <bound method Conv.call of <tensorflow.python.layers.convolutional.Conv2D object at 0x0000029C756D8988>>: AssertionError: Bad argument number for Name: 3, expecting 4\n",
      "WARNING: Entity <bound method Conv.call of <tensorflow.python.layers.convolutional.Conv2D object at 0x0000029C756D8988>> could not be transformed and will be executed as-is. Please report this to the AutgoGraph team. When filing the bug, set the verbosity to 10 (on Linux, `export AUTOGRAPH_VERBOSITY=10`) and attach the full output. Cause: converting <bound method Conv.call of <tensorflow.python.layers.convolutional.Conv2D object at 0x0000029C756D8988>>: AssertionError: Bad argument number for Name: 3, expecting 4\n",
      "WARNING:tensorflow:Entity <bound method Conv.call of <tensorflow.python.layers.convolutional.Conv2D object at 0x0000029C75791FC8>> could not be transformed and will be executed as-is. Please report this to the AutgoGraph team. When filing the bug, set the verbosity to 10 (on Linux, `export AUTOGRAPH_VERBOSITY=10`) and attach the full output. Cause: converting <bound method Conv.call of <tensorflow.python.layers.convolutional.Conv2D object at 0x0000029C75791FC8>>: AssertionError: Bad argument number for Name: 3, expecting 4\n",
      "WARNING: Entity <bound method Conv.call of <tensorflow.python.layers.convolutional.Conv2D object at 0x0000029C75791FC8>> could not be transformed and will be executed as-is. Please report this to the AutgoGraph team. When filing the bug, set the verbosity to 10 (on Linux, `export AUTOGRAPH_VERBOSITY=10`) and attach the full output. Cause: converting <bound method Conv.call of <tensorflow.python.layers.convolutional.Conv2D object at 0x0000029C75791FC8>>: AssertionError: Bad argument number for Name: 3, expecting 4\n",
      "WARNING:tensorflow:Entity <bound method Conv.call of <tensorflow.python.layers.convolutional.Conv2D object at 0x0000029C756D8988>> could not be transformed and will be executed as-is. Please report this to the AutgoGraph team. When filing the bug, set the verbosity to 10 (on Linux, `export AUTOGRAPH_VERBOSITY=10`) and attach the full output. Cause: converting <bound method Conv.call of <tensorflow.python.layers.convolutional.Conv2D object at 0x0000029C756D8988>>: AssertionError: Bad argument number for Name: 3, expecting 4\n",
      "WARNING: Entity <bound method Conv.call of <tensorflow.python.layers.convolutional.Conv2D object at 0x0000029C756D8988>> could not be transformed and will be executed as-is. Please report this to the AutgoGraph team. When filing the bug, set the verbosity to 10 (on Linux, `export AUTOGRAPH_VERBOSITY=10`) and attach the full output. Cause: converting <bound method Conv.call of <tensorflow.python.layers.convolutional.Conv2D object at 0x0000029C756D8988>>: AssertionError: Bad argument number for Name: 3, expecting 4\n",
      "WARNING:tensorflow:Entity <bound method Conv.call of <tensorflow.python.layers.convolutional.Conv2D object at 0x0000029C76CC4408>> could not be transformed and will be executed as-is. Please report this to the AutgoGraph team. When filing the bug, set the verbosity to 10 (on Linux, `export AUTOGRAPH_VERBOSITY=10`) and attach the full output. Cause: converting <bound method Conv.call of <tensorflow.python.layers.convolutional.Conv2D object at 0x0000029C76CC4408>>: AssertionError: Bad argument number for Name: 3, expecting 4\n",
      "WARNING: Entity <bound method Conv.call of <tensorflow.python.layers.convolutional.Conv2D object at 0x0000029C76CC4408>> could not be transformed and will be executed as-is. Please report this to the AutgoGraph team. When filing the bug, set the verbosity to 10 (on Linux, `export AUTOGRAPH_VERBOSITY=10`) and attach the full output. Cause: converting <bound method Conv.call of <tensorflow.python.layers.convolutional.Conv2D object at 0x0000029C76CC4408>>: AssertionError: Bad argument number for Name: 3, expecting 4\n",
      "WARNING:tensorflow:Entity <bound method Pooling2D.call of <tensorflow.python.layers.pooling.MaxPooling2D object at 0x0000029C7511B0C8>> could not be transformed and will be executed as-is. Please report this to the AutgoGraph team. When filing the bug, set the verbosity to 10 (on Linux, `export AUTOGRAPH_VERBOSITY=10`) and attach the full output. Cause: converting <bound method Pooling2D.call of <tensorflow.python.layers.pooling.MaxPooling2D object at 0x0000029C7511B0C8>>: AssertionError: Bad argument number for Name: 3, expecting 4\n"
     ]
    },
    {
     "name": "stdout",
     "output_type": "stream",
     "text": [
      "WARNING: Entity <bound method Pooling2D.call of <tensorflow.python.layers.pooling.MaxPooling2D object at 0x0000029C7511B0C8>> could not be transformed and will be executed as-is. Please report this to the AutgoGraph team. When filing the bug, set the verbosity to 10 (on Linux, `export AUTOGRAPH_VERBOSITY=10`) and attach the full output. Cause: converting <bound method Pooling2D.call of <tensorflow.python.layers.pooling.MaxPooling2D object at 0x0000029C7511B0C8>>: AssertionError: Bad argument number for Name: 3, expecting 4\n",
      "WARNING:tensorflow:From <ipython-input-3-b028688c9636>:47: flatten (from tensorflow.python.layers.core) is deprecated and will be removed in a future version.\n",
      "Instructions for updating:\n",
      "Use keras.layers.flatten instead.\n",
      "WARNING:tensorflow:Entity <bound method Flatten.call of <tensorflow.python.layers.core.Flatten object at 0x0000029C742D4B48>> could not be transformed and will be executed as-is. Please report this to the AutgoGraph team. When filing the bug, set the verbosity to 10 (on Linux, `export AUTOGRAPH_VERBOSITY=10`) and attach the full output. Cause: converting <bound method Flatten.call of <tensorflow.python.layers.core.Flatten object at 0x0000029C742D4B48>>: AttributeError: module 'gast' has no attribute 'Num'\n",
      "WARNING: Entity <bound method Flatten.call of <tensorflow.python.layers.core.Flatten object at 0x0000029C742D4B48>> could not be transformed and will be executed as-is. Please report this to the AutgoGraph team. When filing the bug, set the verbosity to 10 (on Linux, `export AUTOGRAPH_VERBOSITY=10`) and attach the full output. Cause: converting <bound method Flatten.call of <tensorflow.python.layers.core.Flatten object at 0x0000029C742D4B48>>: AttributeError: module 'gast' has no attribute 'Num'\n",
      "WARNING:tensorflow:From <ipython-input-3-b028688c9636>:49: dense (from tensorflow.python.layers.core) is deprecated and will be removed in a future version.\n",
      "Instructions for updating:\n",
      "Use keras.layers.dense instead.\n",
      "WARNING:tensorflow:Entity <bound method Dense.call of <tensorflow.python.layers.core.Dense object at 0x0000029C7511B0C8>> could not be transformed and will be executed as-is. Please report this to the AutgoGraph team. When filing the bug, set the verbosity to 10 (on Linux, `export AUTOGRAPH_VERBOSITY=10`) and attach the full output. Cause: converting <bound method Dense.call of <tensorflow.python.layers.core.Dense object at 0x0000029C7511B0C8>>: AssertionError: Bad argument number for Name: 3, expecting 4\n",
      "WARNING: Entity <bound method Dense.call of <tensorflow.python.layers.core.Dense object at 0x0000029C7511B0C8>> could not be transformed and will be executed as-is. Please report this to the AutgoGraph team. When filing the bug, set the verbosity to 10 (on Linux, `export AUTOGRAPH_VERBOSITY=10`) and attach the full output. Cause: converting <bound method Dense.call of <tensorflow.python.layers.core.Dense object at 0x0000029C7511B0C8>>: AssertionError: Bad argument number for Name: 3, expecting 4\n",
      "WARNING:tensorflow:From D:\\Users\\Charles\\Anaconda3\\lib\\site-packages\\tensorflow\\python\\ops\\losses\\losses_impl.py:121: add_dispatch_support.<locals>.wrapper (from tensorflow.python.ops.array_ops) is deprecated and will be removed in a future version.\n",
      "Instructions for updating:\n",
      "Use tf.where in 2.0, which has the same broadcast rule as np.where\n"
     ]
    }
   ],
   "source": [
    "def separable_conv_block(x, output_channel_number, name):\n",
    "    \"\"\"\n",
    "    output_channel_number: 输出通道数 output channel of 1*1 conv layer\n",
    "    \"\"\"\n",
    "    with tf.variable_scope(name):\n",
    "        input_channel = x.get_shape().as_list()[-1]\n",
    "        channel_wise_x = tf.split(x, input_channel, axis=3)\n",
    "        out_channels = []\n",
    "        for i in range(len(channel_wise_x)):\n",
    "            out_channel = tf.layers.conv2d(channel_wise_x[i], 1, (3, 3), strides=(1, 1), padding='same', activation = tf.nn.relu,\n",
    "                                           name = 'conv_%d' % i)\n",
    "            out_channels.append(out_channel)\n",
    "        concat_layer = tf.concat(out_channels, axis=3)\n",
    "        conv1_1 = tf.layers.conv2d(concat_layer, output_channel_number, (1,1), strides = (1,1), padding = 'same', activation = tf.nn.relu,\n",
    "                                   name = 'conv1_1')\n",
    "    return conv1_1\n",
    "\n",
    "\n",
    "\n",
    "# 计算图模型，先新建计算图，然后将数据塞入计算图中\n",
    "# placeholder 占位符的作用\n",
    "x = tf.placeholder(tf.float32, [None, 3072])  # None 样本数不确定，mini_batch\n",
    "# [None]\n",
    "y = tf.placeholder(tf.int64, [None])\n",
    "\n",
    "# 图片转换，reshape\n",
    "x_image = tf.reshape(x, [-1, 3, 32, 32])\n",
    "# 大小： 32*32\n",
    "x_image = tf.transpose(x_image, perm=[0, 2, 3, 1])\n",
    "\n",
    "conv1 = tf.layers.conv2d(x_image, 32, (3, 3), padding='same', activation=tf.nn.relu, name='conv1')\n",
    "\n",
    "pooling1 = tf.layers.max_pooling2d(conv1, (2, 2), (2, 2), name='pool1')\n",
    "\n",
    "separable_2a = separable_conv_block(pooling1, 32, name='separable_2a')\n",
    "\n",
    "separable_2b = separable_conv_block(separable_2a, 32, name='separable_2b')\n",
    "\n",
    "pooling2 = tf.layers.max_pooling2d(separable_2b, (2, 2), (2, 2), name='pooling2')\n",
    "\n",
    "separable_3a = separable_conv_block(pooling2, 32, name='separable_3a')\n",
    "\n",
    "separable_3b = separable_conv_block(separable_3a, 32, name='separable_3b')\n",
    "\n",
    "pooling3 = tf.layers.max_pooling2d(separable_3b, (2, 2), (2, 2), name='pooling3')\n",
    "\n",
    "flatten = tf.layers.flatten(pooling3)\n",
    "\n",
    "y_ = tf.layers.dense(flatten, 10)\n",
    "\n",
    "# 交叉熵损失数函数\n",
    "loss = tf.losses.sparse_softmax_cross_entropy(labels=y, logits=y_)\n",
    "# 执行原理\n",
    "# y_ -> softmax\n",
    "# y -> one_hot\n",
    "# loss -> ylogy_\n",
    "\n",
    "# 寻找最大概率值的 indices\n",
    "# 1 代表在第一个维度上\n",
    "predict = tf.argmax(y_, 1)\n",
    "# correct_prediction 结果可能是[0,1,0,0,1,1,1]\n",
    "correct_prediction = tf.equal(predict, y)\n",
    "# 求准确率，就是求平均值\n",
    "accuracy = tf.reduce_mean(tf.cast(correct_prediction, tf.float64))\n",
    "\n",
    "# 在我们有了目标函数和损失函数，再定义梯度下降方法\n",
    "# 梯度下降的变种\n",
    "# 优化最小loss的值\n",
    "with tf.name_scope('train_op'):\n",
    "    train_op = tf.train.AdamOptimizer(1e-3).minimize(loss)\n",
    "# 计算图构建完成"
   ]
  },
  {
   "cell_type": "code",
   "execution_count": 4,
   "metadata": {},
   "outputs": [
    {
     "name": "stdout",
     "output_type": "stream",
     "text": [
      "[Train] Step: 100, loss: 2.05502, acc: 0.20000\n",
      "[Train] Step: 200, loss: 1.75660, acc: 0.35000\n",
      "[Train] Step: 300, loss: 1.83929, acc: 0.20000\n",
      "[Train] Step: 400, loss: 1.59586, acc: 0.45000\n",
      "[Train] Step: 500, loss: 1.55205, acc: 0.45000\n",
      "[Train] Step: 600, loss: 1.73806, acc: 0.40000\n",
      "[Train] Step: 700, loss: 1.87275, acc: 0.45000\n",
      "[Train] Step: 800, loss: 1.47101, acc: 0.35000\n",
      "[Train] Step: 900, loss: 1.64832, acc: 0.35000\n",
      "[Train] Step: 1000, loss: 1.09020, acc: 0.70000\n",
      "(10000, 3072)\n",
      "(10000,)\n",
      "[Test ] Step: 1000, acc: 0.43800\n",
      "[Train] Step: 1100, loss: 1.58547, acc: 0.55000\n",
      "[Train] Step: 1200, loss: 1.53803, acc: 0.40000\n",
      "[Train] Step: 1300, loss: 1.34169, acc: 0.60000\n",
      "[Train] Step: 1400, loss: 1.13900, acc: 0.55000\n",
      "[Train] Step: 1500, loss: 1.45179, acc: 0.35000\n",
      "[Train] Step: 1600, loss: 1.60157, acc: 0.55000\n",
      "[Train] Step: 1700, loss: 1.63515, acc: 0.20000\n",
      "[Train] Step: 1800, loss: 1.47493, acc: 0.55000\n",
      "[Train] Step: 1900, loss: 1.18941, acc: 0.70000\n",
      "[Train] Step: 2000, loss: 1.18592, acc: 0.40000\n",
      "(10000, 3072)\n",
      "(10000,)\n",
      "[Test ] Step: 2000, acc: 0.50100\n",
      "[Train] Step: 2100, loss: 1.34208, acc: 0.55000\n",
      "[Train] Step: 2200, loss: 1.89760, acc: 0.40000\n",
      "[Train] Step: 2300, loss: 1.02449, acc: 0.55000\n",
      "[Train] Step: 2400, loss: 1.37114, acc: 0.55000\n",
      "[Train] Step: 2500, loss: 1.16098, acc: 0.65000\n",
      "[Train] Step: 2600, loss: 1.77176, acc: 0.30000\n",
      "[Train] Step: 2700, loss: 1.35928, acc: 0.65000\n",
      "[Train] Step: 2800, loss: 1.37479, acc: 0.55000\n",
      "[Train] Step: 2900, loss: 1.35876, acc: 0.50000\n",
      "[Train] Step: 3000, loss: 1.28654, acc: 0.60000\n",
      "(10000, 3072)\n",
      "(10000,)\n",
      "[Test ] Step: 3000, acc: 0.54950\n",
      "[Train] Step: 3100, loss: 1.45267, acc: 0.50000\n",
      "[Train] Step: 3200, loss: 0.83232, acc: 0.70000\n",
      "[Train] Step: 3300, loss: 1.01187, acc: 0.60000\n",
      "[Train] Step: 3400, loss: 1.01214, acc: 0.65000\n",
      "[Train] Step: 3500, loss: 1.08483, acc: 0.70000\n",
      "[Train] Step: 3600, loss: 1.20248, acc: 0.55000\n",
      "[Train] Step: 3700, loss: 0.97570, acc: 0.70000\n",
      "[Train] Step: 3800, loss: 0.84512, acc: 0.75000\n",
      "[Train] Step: 3900, loss: 1.13197, acc: 0.50000\n",
      "[Train] Step: 4000, loss: 1.11995, acc: 0.65000\n",
      "(10000, 3072)\n",
      "(10000,)\n",
      "[Test ] Step: 4000, acc: 0.57450\n",
      "[Train] Step: 4100, loss: 0.99137, acc: 0.65000\n",
      "[Train] Step: 4200, loss: 1.10025, acc: 0.60000\n",
      "[Train] Step: 4300, loss: 0.63669, acc: 0.80000\n",
      "[Train] Step: 4400, loss: 1.00675, acc: 0.55000\n",
      "[Train] Step: 4500, loss: 1.07619, acc: 0.60000\n",
      "[Train] Step: 4600, loss: 0.70625, acc: 0.85000\n",
      "[Train] Step: 4700, loss: 1.14484, acc: 0.65000\n",
      "[Train] Step: 4800, loss: 1.15294, acc: 0.60000\n",
      "[Train] Step: 4900, loss: 1.57511, acc: 0.45000\n",
      "[Train] Step: 5000, loss: 0.79904, acc: 0.80000\n",
      "(10000, 3072)\n",
      "(10000,)\n",
      "[Test ] Step: 5000, acc: 0.59600\n",
      "[Train] Step: 5100, loss: 1.25801, acc: 0.65000\n",
      "[Train] Step: 5200, loss: 0.91201, acc: 0.70000\n",
      "[Train] Step: 5300, loss: 1.18655, acc: 0.35000\n",
      "[Train] Step: 5400, loss: 1.04546, acc: 0.50000\n",
      "[Train] Step: 5500, loss: 0.51661, acc: 0.90000\n",
      "[Train] Step: 5600, loss: 0.51837, acc: 0.85000\n",
      "[Train] Step: 5700, loss: 1.10036, acc: 0.70000\n",
      "[Train] Step: 5800, loss: 0.92304, acc: 0.75000\n",
      "[Train] Step: 5900, loss: 1.05837, acc: 0.65000\n",
      "[Train] Step: 6000, loss: 1.39225, acc: 0.55000\n",
      "(10000, 3072)\n",
      "(10000,)\n",
      "[Test ] Step: 6000, acc: 0.60650\n",
      "[Train] Step: 6100, loss: 0.92550, acc: 0.60000\n",
      "[Train] Step: 6200, loss: 0.79672, acc: 0.80000\n",
      "[Train] Step: 6300, loss: 0.79717, acc: 0.70000\n",
      "[Train] Step: 6400, loss: 1.09302, acc: 0.60000\n",
      "[Train] Step: 6500, loss: 1.16889, acc: 0.65000\n",
      "[Train] Step: 6600, loss: 1.18548, acc: 0.50000\n",
      "[Train] Step: 6700, loss: 1.40932, acc: 0.50000\n",
      "[Train] Step: 6800, loss: 0.80381, acc: 0.65000\n",
      "[Train] Step: 6900, loss: 0.77360, acc: 0.80000\n",
      "[Train] Step: 7000, loss: 1.38504, acc: 0.45000\n",
      "(10000, 3072)\n",
      "(10000,)\n",
      "[Test ] Step: 7000, acc: 0.62700\n",
      "[Train] Step: 7100, loss: 1.23611, acc: 0.70000\n",
      "[Train] Step: 7200, loss: 1.06118, acc: 0.55000\n",
      "[Train] Step: 7300, loss: 0.80635, acc: 0.65000\n",
      "[Train] Step: 7400, loss: 1.16341, acc: 0.60000\n",
      "[Train] Step: 7500, loss: 1.12245, acc: 0.65000\n",
      "[Train] Step: 7600, loss: 1.60028, acc: 0.50000\n",
      "[Train] Step: 7700, loss: 0.83674, acc: 0.80000\n",
      "[Train] Step: 7800, loss: 0.83034, acc: 0.75000\n",
      "[Train] Step: 7900, loss: 1.32987, acc: 0.50000\n",
      "[Train] Step: 8000, loss: 0.81000, acc: 0.65000\n",
      "(10000, 3072)\n",
      "(10000,)\n",
      "[Test ] Step: 8000, acc: 0.64050\n",
      "[Train] Step: 8100, loss: 0.63222, acc: 0.70000\n",
      "[Train] Step: 8200, loss: 0.69877, acc: 0.70000\n",
      "[Train] Step: 8300, loss: 0.87862, acc: 0.65000\n",
      "[Train] Step: 8400, loss: 0.86310, acc: 0.55000\n",
      "[Train] Step: 8500, loss: 0.98096, acc: 0.80000\n",
      "[Train] Step: 8600, loss: 1.14185, acc: 0.60000\n",
      "[Train] Step: 8700, loss: 0.99313, acc: 0.70000\n",
      "[Train] Step: 8800, loss: 0.66468, acc: 0.80000\n",
      "[Train] Step: 8900, loss: 0.94026, acc: 0.65000\n",
      "[Train] Step: 9000, loss: 0.77615, acc: 0.70000\n",
      "(10000, 3072)\n",
      "(10000,)\n",
      "[Test ] Step: 9000, acc: 0.64450\n",
      "[Train] Step: 9100, loss: 1.11040, acc: 0.70000\n",
      "[Train] Step: 9200, loss: 1.05962, acc: 0.75000\n",
      "[Train] Step: 9300, loss: 0.81931, acc: 0.75000\n",
      "[Train] Step: 9400, loss: 1.17149, acc: 0.60000\n",
      "[Train] Step: 9500, loss: 1.25041, acc: 0.55000\n",
      "[Train] Step: 9600, loss: 1.10148, acc: 0.70000\n",
      "[Train] Step: 9700, loss: 0.80586, acc: 0.75000\n",
      "[Train] Step: 9800, loss: 1.18715, acc: 0.50000\n",
      "[Train] Step: 9900, loss: 1.08774, acc: 0.70000\n",
      "[Train] Step: 10000, loss: 1.67609, acc: 0.35000\n",
      "(10000, 3072)\n",
      "(10000,)\n",
      "[Test ] Step: 10000, acc: 0.65250\n"
     ]
    }
   ],
   "source": [
    "init = tf.global_variables_initializer()\n",
    "batch_size = 20\n",
    "train_steps = 10000\n",
    "test_steps = 100\n",
    "\n",
    "# train 10k: 73.4%\n",
    "with tf.Session() as sess:\n",
    "    sess.run(init)\n",
    "    for i in range(train_steps):\n",
    "        batch_data, batch_labels = train_data.next_batch(batch_size)\n",
    "        loss_val, acc_val, _ = sess.run(\n",
    "            [loss, accuracy, train_op],\n",
    "            feed_dict={\n",
    "                x: batch_data,\n",
    "                y: batch_labels})\n",
    "        if (i+1) % 100 == 0:\n",
    "            print('[Train] Step: %d, loss: %4.5f, acc: %4.5f' \n",
    "                  % (i+1, loss_val, acc_val))\n",
    "        if (i+1) % 1000 == 0:\n",
    "            test_data = CifarData(test_filenames, False)\n",
    "            all_test_acc_val = []\n",
    "            for j in range(test_steps):\n",
    "                test_batch_data, test_batch_labels \\\n",
    "                    = test_data.next_batch(batch_size)\n",
    "                test_acc_val = sess.run(\n",
    "                    [accuracy],\n",
    "                    feed_dict = {\n",
    "                        x: test_batch_data, \n",
    "                        y: test_batch_labels\n",
    "                    })\n",
    "                all_test_acc_val.append(test_acc_val)\n",
    "            test_acc = np.mean(all_test_acc_val)\n",
    "            print('[Test ] Step: %d, acc: %4.5f' % (i+1, test_acc))"
   ]
  },
  {
   "cell_type": "code",
   "execution_count": null,
   "metadata": {},
   "outputs": [],
   "source": []
  }
 ],
 "metadata": {
  "kernelspec": {
   "display_name": "Python 3",
   "language": "python",
   "name": "python3"
  },
  "language_info": {
   "codemirror_mode": {
    "name": "ipython",
    "version": 3
   },
   "file_extension": ".py",
   "mimetype": "text/x-python",
   "name": "python",
   "nbconvert_exporter": "python",
   "pygments_lexer": "ipython3",
   "version": "3.7.4"
  }
 },
 "nbformat": 4,
 "nbformat_minor": 2
}
